Workbook

Sheet OUTLET WISE  
A1: Outlet Wise Report APRIL 2023
A2: Outlet | B2: Outlet | C2: Booking | D2: Retail | E2: SBI & Other Banks | F2: In House | G2: Pending Login | H2: SBI Pending Login | I2: Pent% | J2: CF | K2: MSSF DISBURSED
A3: ALUVA | B3: ALVA | C3: =COUNTIF(Booking!#REF!,B3) -> #REF! | D3: =COUNTIF(RETAIL!#REF!,B3) -> #REF! | E3: =COUNTIFS(#REF!,+B3,#REF!,"=DISBURSED") -> #REF! | F3: =COUNTIFS(IH!#REF!,+B3,IH!#REF!,"=DISBURSED") -> #REF! | G3: =COUNTIFS(IH!#REF!,+B3,IH!#REF!,"=LOGIN")+COUNTIFS(IH!#REF!,+B3,IH!#REF!,"=APPROVED") -> #REF! | H3: =COUNTIFS(#REF!,+B3,#REF!,"=LOGIN")+COUNTIFS(#REF!,B3,#REF!,"=APPROVED") -> #REF! | I3: =(E3+F3)/D3 -> #REF! | J3: =COUNTIFS(RETAIL!#REF!,+B3,RETAIL!P:P,"=C/F") -> #REF! | K3: 2
A4: ANGAMALY | B4: ANGLY | C4: =COUNTIF(Booking!#REF!,B4) -> #REF! | D4: =COUNTIF(RETAIL!#REF!,B4) -> #REF! | E4: =COUNTIFS(#REF!,+B4,#REF!,"=DISBURSED") -> #REF! | F4: =COUNTIFS(IH!#REF!,+B4,IH!#REF!,"=DISBURSED") -> #REF! | G4: =COUNTIFS(IH!#REF!,+B4,IH!#REF!,"=LOGIN")+COUNTIFS(IH!#REF!,+B4,IH!#REF!,"=APPROVED") -> #REF! | H4: =COUNTIFS(#REF!,+B4,#REF!,"=LOGIN")+COUNTIFS(#REF!,B4,#REF!,"=APPROVED") -> #REF! | I4: =(E4+F4)/D4 -> #REF! | J4: =COUNTIFS(RETAIL!#REF!,+B4,RETAIL!P:P,"=C/F") -> #REF! | K4: 4
A5: CHAVAKKAD | B5: CHVKD | C5: =COUNTIF(Booking!#REF!,B5) -> #REF! | D5: =COUNTIF(RETAIL!#REF!,B5) -> #REF! | E5: =COUNTIFS(#REF!,+B5,#REF!,"=DISBURSED") -> #REF! | F5: =COUNTIFS(IH!#REF!,+B5,IH!#REF!,"=DISBURSED") -> #REF! | G5: =COUNTIFS(IH!#REF!,+B5,IH!#REF!,"=LOGIN")+COUNTIFS(IH!#REF!,+B5,IH!#REF!,"=APPROVED") -> #REF! | H5: =COUNTIFS(#REF!,+B5,#REF!,"=LOGIN")+COUNTIFS(#REF!,B5,#REF!,"=APPROVED") -> #REF! | I5: =(E5+F5)/D5 -> #REF! | J5: =COUNTIFS(RETAIL!#REF!,+B5,RETAIL!P:P,"=C/F") -> #REF! | K5: 3
A6: EDAPPALLY | B6: EDPLY | C6: =COUNTIF(Booking!#REF!,B6) -> #REF! | D6: =COUNTIF(RETAIL!#REF!,B6) -> #REF! | E6: =COUNTIFS(#REF!,+B6,#REF!,"=DISBURSED") -> #REF! | F6: =COUNTIFS(IH!#REF!,+B6,IH!#REF!,"=DISBURSED") -> #REF! | G6: =COUNTIFS(IH!#REF!,+B6,IH!#REF!,"=LOGIN")+COUNTIFS(IH!#REF!,+B6,IH!#REF!,"=APPROVED") -> #REF! | H6: =COUNTIFS(#REF!,+B6,#REF!,"=LOGIN")+COUNTIFS(#REF!,B6,#REF!,"=APPROVED") -> #REF! | I6: =(E6+F6)/D6 -> #REF! | J6: =COUNTIFS(RETAIL!#REF!,+B6,RETAIL!P:P,"=C/F") -> #REF! | K6: 4
A7: KADAVANTHRA | B7: KDVRA | C7: =COUNTIF(Booking!#REF!,B7) -> #REF! | D7: =COUNTIF(RETAIL!#REF!,B7) -> #REF! | E7: =COUNTIFS(#REF!,+B7,#REF!,"=DISBURSED") -> #REF! | F7: =COUNTIFS(IH!#REF!,+B7,IH!#REF!,"=DISBURSED") -> #REF! | G7: =COUNTIFS(IH!#REF!,+B7,IH!#REF!,"=LOGIN")+COUNTIFS(IH!#REF!,+B7,IH!#REF!,"=APPROVED") -> #REF! | H7: =COUNTIFS(#REF!,+B7,#REF!,"=LOGIN")+COUNTIFS(#REF!,B7,#REF!,"=APPROVED") -> #REF! | I7: =(E7+F7)/D7 -> #REF! | J7: =COUNTIFS(RETAIL!#REF!,+B7,RETAIL!P:P,"=C/F") -> #REF! | K7: 3
A8: KODUNGALLOOR | B8: KDLR | C8: =COUNTIF(Booking!#REF!,B8) -> #REF! | D8: =COUNTIF(RETAIL!#REF!,B8) -> #REF! | E8: =COUNTIFS(#REF!,+B8,#REF!,"=DISBURSED") -> #REF! | F8: =COUNTIFS(IH!#REF!,+B8,IH!#REF!,"=DISBURSED") -> #REF! | G8: =COUNTIFS(IH!#REF!,+B8,IH!#REF!,"=LOGIN")+COUNTIFS(IH!#REF!,+B8,IH!#REF!,"=APPROVED") -> #REF! | H8: =COUNTIFS(#REF!,+B8,#REF!,"=LOGIN")+COUNTIFS(#REF!,B8,#REF!,"=APPROVED") -> #REF! | I8: =(E8+F8)/D8 -> #REF! | J8: =COUNTIFS(RETAIL!#REF!,+B8,RETAIL!P:P,"=C/F") -> #REF! | K8: 1
A9: KAIPAMANGALAM | B9: KPLM | C9: =COUNTIF(Booking!#REF!,B9) -> #REF! | D9: =COUNTIF(RETAIL!#REF!,B9) -> #REF! | E9: =COUNTIFS(#REF!,+B9,#REF!,"=DISBURSED") -> #REF! | F9: =COUNTIFS(IH!#REF!,+B9,IH!#REF!,"=DISBURSED") -> #REF! | G9: =COUNTIFS(IH!#REF!,+B9,IH!#REF!,"=LOGIN")+COUNTIFS(IH!#REF!,+B9,IH!#REF!,"=APPROVED") -> #REF! | H9: =COUNTIFS(#REF!,+B9,#REF!,"=LOGIN")+COUNTIFS(#REF!,B9,#REF!,"=APPROVED") -> #REF! | I9: =(E9+F9)/D9 -> #REF! | J9: =COUNTIFS(RETAIL!#REF!,+B9,RETAIL!P:P,"=C/F") -> #REF! | K9: 5
A10: KOOTHATTUKULAM | B10: KTLM | C10: =COUNTIF(Booking!#REF!,B10) -> #REF! | D10: =COUNTIF(RETAIL!#REF!,B10) -> #REF! | E10: =COUNTIFS(#REF!,+B10,#REF!,"=DISBURSED") -> #REF! | F10: =COUNTIFS(IH!#REF!,+B10,IH!#REF!,"=DISBURSED") -> #REF! | G10: =COUNTIFS(IH!#REF!,+B10,IH!#REF!,"=LOGIN")+COUNTIFS(IH!#REF!,+B10,IH!#REF!,"=APPROVED") -> #REF! | H10: =COUNTIFS(#REF!,+B10,#REF!,"=LOGIN")+COUNTIFS(#REF!,B10,#REF!,"=APPROVED") -> #REF! | I10: =(E10+F10)/D10 -> #REF! | J10: =COUNTIFS(RETAIL!#REF!,+B10,RETAIL!P:P,"=C/F") -> #REF! | K10: 1
A11: KOLENCHERRY | B11: KLY | C11: =COUNTIF(Booking!#REF!,B11) -> #REF! | D11: =COUNTIF(RETAIL!#REF!,B11) -> #REF! | E11: =COUNTIFS(#REF!,+B11,#REF!,"=DISBURSED") -> #REF! | F11: =COUNTIFS(IH!#REF!,+B11,IH!#REF!,"=DISBURSED") -> #REF! | G11: =COUNTIFS(IH!#REF!,+B11,IH!#REF!,"=LOGIN")+COUNTIFS(IH!#REF!,+B11,IH!#REF!,"=APPROVED") -> #REF! | H11: =COUNTIFS(#REF!,+B11,#REF!,"=LOGIN")+COUNTIFS(#REF!,B11,#REF!,"=APPROVED") -> #REF! | I11: =(E11+F11)/D11 -> #REF! | J11: =COUNTIFS(RETAIL!#REF!,+B11,RETAIL!P:P,"=C/F") -> #REF! | K11: 2
A12: PERUMBAVOOR | B12: PMBR | C12: =COUNTIF(Booking!#REF!,B12) -> #REF! | D12: =COUNTIF(RETAIL!#REF!,B12) -> #REF! | E12: =COUNTIFS(#REF!,+B12,#REF!,"=DISBURSED") -> #REF! | F12: =COUNTIFS(IH!#REF!,+B12,IH!#REF!,"=DISBURSED") -> #REF! | G12: =COUNTIFS(IH!#REF!,+B12,IH!#REF!,"=LOGIN")+COUNTIFS(IH!#REF!,+B12,IH!#REF!,"=APPROVED") -> #REF! | H12: =COUNTIFS(#REF!,+B12,#REF!,"=LOGIN")+COUNTIFS(#REF!,B12,#REF!,"=APPROVED") -> #REF! | I12: =(E12+F12)/D12 -> #REF! | J12: =COUNTIFS(RETAIL!#REF!,+B12,RETAIL!P:P,"=C/F") -> #REF! | K12: 4
A13: PALAKKAD | B13: PLKD | C13: =COUNTIF(Booking!#REF!,B13) -> #REF! | D13: =COUNTIF(RETAIL!#REF!,B13) -> #REF! | E13: =COUNTIFS(#REF!,+B13,#REF!,"=DISBURSED") -> #REF! | F13: =COUNTIFS(IH!#REF!,+B13,IH!#REF!,"=DISBURSED") -> #REF! | G13: =COUNTIFS(IH!#REF!,+B13,IH!#REF!,"=LOGIN")+COUNTIFS(IH!#REF!,+B13,IH!#REF!,"=APPROVED") -> #REF! | H13: =COUNTIFS(#REF!,+B13,#REF!,"=LOGIN")+COUNTIFS(#REF!,B13,#REF!,"=APPROVED") -> #REF! | I13: =(E13+F13)/D13 -> #REF! | J13: =COUNTIFS(RETAIL!#REF!,+B13,RETAIL!P:P,"=C/F") -> #REF! | K13: 1
A14: FORTKOCHI | B14: FORTKOCHI | C14: =COUNTIF(Booking!#REF!,B14) -> #REF! | D14: =COUNTIF(RETAIL!#REF!,B14) -> #REF! | E14: =COUNTIFS(#REF!,+B14,#REF!,"=DISBURSED") -> #REF! | F14: =COUNTIFS(IH!#REF!,+B14,IH!#REF!,"=DISBURSED") -> #REF! | G14: =COUNTIFS(IH!#REF!,+B14,IH!#REF!,"=LOGIN")+COUNTIFS(IH!#REF!,+B14,IH!#REF!,"=APPROVED") -> #REF! | H14: =COUNTIFS(#REF!,+B14,#REF!,"=LOGIN")+COUNTIFS(#REF!,B14,#REF!,"=APPROVED") -> #REF! | I14: =(E14+F14)/D14 -> #REF! | J14: =COUNTIFS(RETAIL!#REF!,+B14,RETAIL!P:P,"=C/F") -> #REF! | K14: 1
... A19: NEXA | B19: NEXA | C19: =COUNTIF(Booking!#REF!,B19) -> #REF! | D19: =COUNTIF(RETAIL!#REF!,B19) -> #REF! | E19: =COUNTIFS(#REF!,+B19,#REF!,"=DISBURSED") -> #REF! | F19: =COUNTIFS(IH!#REF!,+B19,IH!#REF!,"=DISBURSED") -> #REF! | G19: =COUNTIFS(IH!#REF!,+B19,IH!#REF!,"=LOGIN")+COUNTIFS(IH!#REF!,+B19,IH!#REF!,"=APPROVED") -> #REF! | H19: =COUNTIFS(#REF!,+B19,#REF!,"=LOGIN")+COUNTIFS(#REF!,B19,#REF!,"=APPROVED") -> #REF! | I19: =(E19+F19)/D19 -> #REF! | J19: =COUNTIFS(RETAIL!#REF!,+B19,RETAIL!P:P,"=C/F") -> #REF! | K19: 3
A20: Total | C20: =SUM(C3:C19) -> #REF! | D20: =SUM(D3:D19) -> #REF! | E20: =SUM(E3:E19) -> #REF! | F20: =SUM(F3:F19) -> #REF! | G20: =SUM(G3:G19) -> #REF! | H20: =SUM(H3:H19) -> #REF! | I20: =(E20+F20)/D20 -> #REF! | J20: =SUM(J3:J19) -> #REF! | K20: 56

Sheet DSE
B1: DSE PERFORMANCE - Mar-26 | E1: ARENA | H1: NEXA | K1: TOTAL
B2: DSE | C2: SRM | D2: OUTLET | E2: RETAIL | F2: IH | G2: PENT% | H2: RETAIL | I2: IH | J2: PENT% | K2: RETAIL | L2: IH | M2: PENT%
B3: SALIH M S | C3: JAYESH | D3: ALUVA | E3: =COUNTIFS(RETAIL!L:L,B3) -> 0 | F3: =COUNTIFS(IH!K:K,B3,IH!S:S,"DISBURSED") -> 0 | G3: =IFERROR((F3/E3),0) -> 0 | H3: =COUNTIFS([1]RETAIL!$L:$L,B3) -> 0 | I3: =COUNTIFS([1]IH!$S:$S,"DISBURSED",[1]IH!$K:$K,B3) -> 0 | J3: =IFERROR((I3/H3),0) -> 0 | K3: =E3+H3 -> 0 | L3: =F3+I3 -> 0 | M3: =IFERROR((L3/K3),0) -> 0
B4: PRAVEEN KUMAR B | C4: ELDHO A JACOB | D4: ANGAMALY | E4: =COUNTIFS(RETAIL!L:L,B4) -> 2 | F4: =COUNTIFS(IH!K:K,B4,IH!S:S,"DISBURSED") -> 1 | G4: =IFERROR((F4/E4),0) -> 0.5 | H4: =COUNTIFS([1]RETAIL!$L:$L,B4) -> 1 | I4: =COUNTIFS([1]IH!$S:$S,"DISBURSED",[1]IH!$K:$K,B4) -> 1 | J4: =IFERROR((I4/H4),0) -> 1 | K4: =E4+H4 -> 3 | L4: =F4+I4 -> 2 | M4: =IFERROR((L4/K4),0) -> 0.66666667
B5: SREEJITH P P | C5: ELDHO A JACOB | D5: ANGAMALY | E5: =COUNTIFS(RETAIL!L:L,B5) -> 0 | F5: =COUNTIFS(IH!K:K,B5,IH!S:S,"DISBURSED") -> 0 | G5: =IFERROR((F5/E5),0) -> 0 | H5: =COUNTIFS([1]RETAIL!$L:$L,B5) -> 0 | I5: =COUNTIFS([1]IH!$S:$S,"DISBURSED",[1]IH!$K:$K,B5) -> 0 | J5: =IFERROR((I5/H5),0) -> 0 | K5: =E5+H5 -> 0 | L5: =F5+I5 -> 0 | M5: =IFERROR((L5/K5),0) -> 0
B6: AMEENSHAH | C6: BHAGIESH | D6: CHAVAKKAD | E6: =COUNTIFS(RETAIL!L:L,B6) -> 0 | F6: =COUNTIFS(IH!K:K,B6,IH!S:S,"DISBURSED") -> 0 | G6: =IFERROR((F6/E6),0) -> 0 | H6: =COUNTIFS([1]RETAIL!$L:$L,B6) -> 0 | I6: =COUNTIFS([1]IH!$S:$S,"DISBURSED",[1]IH!$K:$K,B6) -> 0 | J6: =IFERROR((I6/H6),0) -> 0 | K6: =E6+H6 -> 0 | L6: =F6+I6 -> 0 | M6: =IFERROR((L6/K6),0) -> 0
B7: AKHIL M B | C7: BHAGIESH | D7: CHAVAKKAD | E7: =COUNTIFS(RETAIL!L:L,B7) -> 0 | F7: =COUNTIFS(IH!K:K,B7,IH!S:S,"DISBURSED") -> 0 | G7: =IFERROR((F7/E7),0) -> 0 | H7: =COUNTIFS([1]RETAIL!$L:$L,B7) -> 0 | I7: =COUNTIFS([1]IH!$S:$S,"DISBURSED",[1]IH!$K:$K,B7) -> 0 | J7: =IFERROR((I7/H7),0) -> 0 | K7: =E7+H7 -> 0 | L7: =F7+I7 -> 0 | M7: =IFERROR((L7/K7),0) -> 0
B8: JITHIN CHANDRAN K C | C8: BHAGIESH | D8: CHAVAKKAD | E8: =COUNTIFS(RETAIL!L:L,B8) -> 1 | F8: =COUNTIFS(IH!K:K,B8,IH!S:S,"DISBURSED") -> 1 | G8: =IFERROR((F8/E8),0) -> 1 | H8: =COUNTIFS([1]RETAIL!$L:$L,B8) -> 0 | I8: =COUNTIFS([1]IH!$S:$S,"DISBURSED",[1]IH!$K:$K,B8) -> 0 | J8: =IFERROR((I8/H8),0) -> 0 | K8: =E8+H8 -> 1 | L8: =F8+I8 -> 1 | M8: =IFERROR((L8/K8),0) -> 1
B9: JOHNSON C D | C9: BHAGIESH | D9: CHAVAKKAD | E9: =COUNTIFS(RETAIL!L:L,B9) -> 0 | F9: =COUNTIFS(IH!K:K,B9,IH!S:S,"DISBURSED") -> 0 | G9: =IFERROR((F9/E9),0) -> 0 | H9: =COUNTIFS([1]RETAIL!$L:$L,B9) -> 0 | I9: =COUNTIFS([1]IH!$S:$S,"DISBURSED",[1]IH!$K:$K,B9) -> 0 | J9: =IFERROR((I9/H9),0) -> 0 | K9: =E9+H9 -> 0 | L9: =F9+I9 -> 0 | M9: =IFERROR((L9/K9),0) -> 0
B10: MIDHUL V M | C10: BHAGIESH | D10: CHAVAKKAD | E10: =COUNTIFS(RETAIL!L:L,B10) -> 0 | F10: =COUNTIFS(IH!K:K,B10,IH!S:S,"DISBURSED") -> 0 | G10: =IFERROR((F10/E10),0) -> 0 | H10: =COUNTIFS([1]RETAIL!$L:$L,B10) -> 1 | I10: =COUNTIFS([1]IH!$S:$S,"DISBURSED",[1]IH!$K:$K,B10) -> 0 | J10: =IFERROR((I10/H10),0) -> 0 | K10: =E10+H10 -> 1 | L10: =F10+I10 -> 0 | M10: =IFERROR((L10/K10),0) -> 0
B11: RISHAD K S | C11: BHAGIESH | D11: CHAVAKKAD | E11: =COUNTIFS(RETAIL!L:L,B11) -> 5 | F11: =COUNTIFS(IH!K:K,B11,IH!S:S,"DISBURSED") -> 4 | G11: =IFERROR((F11/E11),0) -> 0.8 | H11: =COUNTIFS([1]RETAIL!$L:$L,B11) -> 3 | I11: =COUNTIFS([1]IH!$S:$S,"DISBURSED",[1]IH!$K:$K,B11) -> 2 | J11: =IFERROR((I11/H11),0) -> 0.66666667 | K11: =E11+H11 -> 8 | L11: =F11+I11 -> 6 | M11: =IFERROR((L11/K11),0) -> 0.75
B12: ABHILASH P C | C12: ABHILASH K P | D12: EDAPPALLY | E12: =COUNTIFS(RETAIL!L:L,B12) -> 10 | F12: =COUNTIFS(IH!K:K,B12,IH!S:S,"DISBURSED") -> 2 | G12: =IFERROR((F12/E12),0) -> 0.2 | H12: =COUNTIFS([1]RETAIL!$L:$L,B12) -> 0 | I12: =COUNTIFS([1]IH!$S:$S,"DISBURSED",[1]IH!$K:$K,B12) -> 0 | J12: =IFERROR((I12/H12),0) -> 0 | K12: =E12+H12 -> 10 | L12: =F12+I12 -> 2 | M12: =IFERROR((L12/K12),0) -> 0.2
B13: MANOJ C S | C13: ABHILASH K P | D13: EDAPPALLY | E13: =COUNTIFS(RETAIL!L:L,B13) -> 3 | F13: =COUNTIFS(IH!K:K,B13,IH!S:S,"DISBURSED") -> 1 | G13: =IFERROR((F13/E13),0) -> 0.33333333 | H13: =COUNTIFS([1]RETAIL!$L:$L,B13) -> 0 | I13: =COUNTIFS([1]IH!$S:$S,"DISBURSED",[1]IH!$K:$K,B13) -> 0 | J13: =IFERROR((I13/H13),0) -> 0 | K13: =E13+H13 -> 3 | L13: =F13+I13 -> 1 | M13: =IFERROR((L13/K13),0) -> 0.33333333
B14: LANEESH A S | C14: MANU SASI | D14: EDAPPALLY | E14: =COUNTIFS(RETAIL!L:L,B14) -> 7 | F14: =COUNTIFS(IH!K:K,B14,IH!S:S,"DISBURSED") -> 6 | G14: =IFERROR((F14/E14),0) -> 0.85714286 | H14: =COUNTIFS([1]RETAIL!$L:$L,B14) -> 3 | I14: =COUNTIFS([1]IH!$S:$S,"DISBURSED",[1]IH!$K:$K,B14) -> 2 | J14: =IFERROR((I14/H14),0) -> 0.66666667 | K14: =E14+H14 -> 10 | L14: =F14+I14 -> 8 | M14: =IFERROR((L14/K14),0) -> 0.8
... B173: EBIN | C173: GEORGE KUTTAN JOY | D173: NEXA COCHIN | E173: =COUNTIFS(RETAIL!L:L,B173) -> 0 | F173: =COUNTIFS(IH!K:K,B173,IH!S:S,"DISBURSED") -> 0 | G173: =IFERROR((F173/E173),0) -> 0 | H173: =COUNTIFS([1]RETAIL!$L:$L,B173) -> 0 | I173: =COUNTIFS([1]IH!$S:$S,"DISBURSED",[1]IH!$K:$K,B173) -> 0 | J173: =IFERROR((I173/H173),0) -> 0 | K173: =E173+H173 -> 0 | L173: =F173+I173 -> 0 | M173: =IFERROR((L173/K173),0) -> 0
B174: TOTAL | E174: =SUM(E3:E173) -> 185 | F174: =SUM(F3:F173) -> 109 | G174: =IFERROR((F174/E174),0) -> 0.58918919 | H174: =SUM(H3:H173) -> 125 | I174: =SUM(I3:I173) -> 88 | J174: =IFERROR(I174/H174,0) -> 0.704 | K174: =E174+H174 -> 310 | L174: =F174+I174 -> 197 | M174: =IFERROR(L174/K174,0) -> 0.63548387

Sheet TL
B1: SRM WISE PERFORMANCE - Mar-26 | H1: NEXA | K1: TOTAL
B2: SRM | C2: OUTLET | D2: RETAIL | E2: IH | F2: PENT% | G2: - | H2: RETAIL | I2: IH | J2: PENT% | K2: RETAIL | L2: IH | M2: PENT%
B3: JAYESH | C3: ALUVA | D3: =COUNTIFS(RETAIL!M:M,+B3) -> 1 | E3: =COUNTIFS(IH!L:L,B3,IH!S:S,"DISBURSED") -> 0 | F3: =IFERROR(E3/D3,0) -> 0 | H3: =COUNTIFS([1]RETAIL!$M:$M,B3) -> 0 | I3: =COUNTIFS([1]IH!$S:$S,"DISBURSED",[1]IH!$L:$L,B3) -> 0 | J3: =IFERROR(I3/H3,0) -> 0 | K3: =D3+H3 -> 1 | L3: =E3+I3 -> 0 | M3: =IFERROR(L3/K3,0) -> 0
B4: ELDHO A JACOB | C4: ANGAMALY | D4: =COUNTIFS(RETAIL!M:M,+B4) -> 5 | E4: =COUNTIFS(IH!L:L,B4,IH!S:S,"DISBURSED") -> 4 | F4: =IFERROR(E4/D4,0) -> 0.8 | H4: =COUNTIFS([1]RETAIL!$M:$M,B4) -> 2 | I4: =COUNTIFS([1]IH!$S:$S,"DISBURSED",[1]IH!$L:$L,B4) -> 2 | J4: =IFERROR(I4/H4,0) -> 1 | K4: =D4+H4 -> 7 | L4: =E4+I4 -> 6 | M4: =IFERROR(L4/K4,0) -> 0.85714286
B5: BHAGIESH | C5: CHAVAKKAD | D5: =COUNTIFS(RETAIL!M:M,+B5) -> 9 | E5: =COUNTIFS(IH!L:L,B5,IH!S:S,"DISBURSED") -> 8 | F5: =IFERROR(E5/D5,0) -> 0.88888889 | H5: =COUNTIFS([1]RETAIL!$M:$M,B5) -> 5 | I5: =COUNTIFS([1]IH!$S:$S,"DISBURSED",[1]IH!$L:$L,B5) -> 3 | J5: =IFERROR(I5/H5,0) -> 0.6 | K5: =D5+H5 -> 14 | L5: =E5+I5 -> 11 | M5: =IFERROR(L5/K5,0) -> 0.78571429
B6: ABHILASH K P | C6: EDAPPALLY | D6: =COUNTIFS(RETAIL!M:M,+B6) -> 13 | E6: =COUNTIFS(IH!L:L,B6,IH!S:S,"DISBURSED") -> 3 | F6: =IFERROR(E6/D6,0) -> 0.23076923 | H6: =COUNTIFS([1]RETAIL!$M:$M,B6) -> 0 | I6: =COUNTIFS([1]IH!$S:$S,"DISBURSED",[1]IH!$L:$L,B6) -> 0 | J6: =IFERROR(I6/H6,0) -> 0 | K6: =D6+H6 -> 13 | L6: =E6+I6 -> 3 | M6: =IFERROR(L6/K6,0) -> 0.23076923
B7: MANU SASI | C7: EDAPPALLY | D7: =COUNTIFS(RETAIL!M:M,+B7) -> 11 | E7: =COUNTIFS(IH!L:L,B7,IH!S:S,"DISBURSED") -> 8 | F7: =IFERROR(E7/D7,0) -> 0.72727273 | H7: =COUNTIFS([1]RETAIL!$M:$M,B7) -> 4 | I7: =COUNTIFS([1]IH!$S:$S,"DISBURSED",[1]IH!$L:$L,B7) -> 2 | J7: =IFERROR(I7/H7,0) -> 0.5 | K7: =D7+H7 -> 15 | L7: =E7+I7 -> 10 | M7: =IFERROR(L7/K7,0) -> 0.66666667
B8: NOUFAL T A | C8: EDAPPALLY | D8: =COUNTIFS(RETAIL!M:M,+B8) -> 7 | E8: =COUNTIFS(IH!L:L,B8,IH!S:S,"DISBURSED") -> 5 | F8: =IFERROR(E8/D8,0) -> 0.71428571 | H8: =COUNTIFS([1]RETAIL!$M:$M,B8) -> 2 | I8: =COUNTIFS([1]IH!$S:$S,"DISBURSED",[1]IH!$L:$L,B8) -> 2 | J8: =IFERROR(I8/H8,0) -> 1 | K8: =D8+H8 -> 9 | L8: =E8+I8 -> 7 | M8: =IFERROR(L8/K8,0) -> 0.77777778
B9: SHEMEER A K | C9: EDAPPALLY | D9: =COUNTIFS(RETAIL!M:M,+B9) -> 4 | E9: =COUNTIFS(IH!L:L,B9,IH!S:S,"DISBURSED") -> 4 | F9: =IFERROR(E9/D9,0) -> 1 | H9: =COUNTIFS([1]RETAIL!$M:$M,B9) -> 1 | I9: =COUNTIFS([1]IH!$S:$S,"DISBURSED",[1]IH!$L:$L,B9) -> 1 | J9: =IFERROR(I9/H9,0) -> 1 | K9: =D9+H9 -> 5 | L9: =E9+I9 -> 5 | M9: =IFERROR(L9/K9,0) -> 1
B10: REJIM GEORGE | C10: FORTKOCHI | D10: =COUNTIFS(RETAIL!M:M,+B10) -> 4 | E10: =COUNTIFS(IH!L:L,B10,IH!S:S,"DISBURSED") -> 3 | F10: =IFERROR(E10/D10,0) -> 0.75 | H10: =COUNTIFS([1]RETAIL!$M:$M,B10) -> 1 | I10: =COUNTIFS([1]IH!$S:$S,"DISBURSED",[1]IH!$L:$L,B10) -> 1 | J10: =IFERROR(I10/H10,0) -> 1 | K10: =D10+H10 -> 5 | L10: =E10+I10 -> 4 | M10: =IFERROR(L10/K10,0) -> 0.8
B11: RATISH K R | C11: KADAVANTHRA | D11: =COUNTIFS(RETAIL!M:M,+B11) -> 8 | E11: =COUNTIFS(IH!L:L,B11,IH!S:S,"DISBURSED") -> 5 | F11: =IFERROR(E11/D11,0) -> 0.625 | H11: =COUNTIFS([1]RETAIL!$M:$M,B11) -> 3 | I11: =COUNTIFS([1]IH!$S:$S,"DISBURSED",[1]IH!$L:$L,B11) -> 3 | J11: =IFERROR(I11/H11,0) -> 1 | K11: =D11+H11 -> 11 | L11: =E11+I11 -> 8 | M11: =IFERROR(L11/K11,0) -> 0.72727273
B12: SMITHIN P S | C12: KAIPAMANGALAM | D12: =COUNTIFS(RETAIL!M:M,+B12) -> 5 | E12: =COUNTIFS(IH!L:L,B12,IH!S:S,"DISBURSED") -> 1 | F12: =IFERROR(E12/D12,0) -> 0.2 | H12: =COUNTIFS([1]RETAIL!$M:$M,B12) -> 1 | I12: =COUNTIFS([1]IH!$S:$S,"DISBURSED",[1]IH!$L:$L,B12) -> 1 | J12: =IFERROR(I12/H12,0) -> 1 | K12: =D12+H12 -> 6 | L12: =E12+I12 -> 2 | M12: =IFERROR(L12/K12,0) -> 0.33333333
B13: VIBIN I B | C13: KAIPAMANGALAM | D13: =COUNTIFS(RETAIL!M:M,+B13) -> 5 | E13: =COUNTIFS(IH!L:L,B13,IH!S:S,"DISBURSED") -> 5 | F13: =IFERROR(E13/D13,0) -> 1 | H13: =COUNTIFS([1]RETAIL!$M:$M,B13) -> 5 | I13: =COUNTIFS([1]IH!$S:$S,"DISBURSED",[1]IH!$L:$L,B13) -> 5 | J13: =IFERROR(I13/H13,0) -> 1 | K13: =D13+H13 -> 10 | L13: =E13+I13 -> 10 | M13: =IFERROR(L13/K13,0) -> 1
B14: KASI VISWANATH | C14: KAIPAMANGALAM | D14: =COUNTIFS(RETAIL!M:M,+B14) -> 9 | E14: =COUNTIFS(IH!L:L,B14,IH!S:S,"DISBURSED") -> 5 | F14: =IFERROR(E14/D14,0) -> 0.55555556 | H14: =COUNTIFS([1]RETAIL!$M:$M,B14) -> 0 | I14: =COUNTIFS([1]IH!$S:$S,"DISBURSED",[1]IH!$L:$L,B14) -> 0 | J14: =IFERROR(I14/H14,0) -> 0 | K14: =D14+H14 -> 9 | L14: =E14+I14 -> 5 | M14: =IFERROR(L14/K14,0) -> 0.55555556
... B32: SACHIN | C32: KODUNGALLUR | D32: =COUNTIFS(RETAIL!M:M,+B32) -> 5 | E32: =COUNTIFS(IH!L:L,B32,IH!S:S,"DISBURSED") -> 3 | F32: =IFERROR(E32/D32,0) -> 0.6 | H32: =COUNTIFS([1]RETAIL!$M:$M,B32) -> 4 | I32: =COUNTIFS([1]IH!$S:$S,"DISBURSED",[1]IH!$L:$L,B32) -> 3 | J32: =IFERROR(I32/H32,0) -> 0.75 | K32: =D32+H32 -> 9 | L32: =E32+I32 -> 6 | M32: =IFERROR(L32/K32,0) -> 0.66666667
C33: TOTAL | D33: =SUM(D3:D32) -> 182 | E33: =SUM(E3:E32) -> 109 | F33: =IFERROR(E33/D33,0) -> 0.5989011 | H33: =SUM(H3:H32) -> 116 | I33: =SUM(I3:I32) -> 85 | J33: =IFERROR(I33/H33,0) -> 0.73275862 | K33: =SUM(K4:K32) -> 297 | L33: =SUM(L3:L32) -> 194 | M33: =IFERROR(L33/K33,0) -> 0.65319865

Sheet Outlet
B1: Arena Outletwise Performance - Mar-26 | L1: Finance Cordinator wise Performance - Mar-26
B2: Outlet Location | C2: Bking | D2: Retail | E2: IH | F2: Login | G2: Pent% | H2: Mssf Login | I2: Mssf Disb | J2: Cordinator | M2: ARENA | P2: NEXA | S2: TOTAL
B3: ALUVA | C3: =COUNTIFS(Booking!C:C,B3) -> 5 | D3: =COUNTIFS(RETAIL!N:N,B3) -> 1 | E3: =COUNTIFS(IH!M:M,B3,IH!S:S,"DISBURSED") -> 0 | F3: =COUNTIFS(IH!M:M,B3,IH!S:S,"LOGIN") -> 0 | G3: =IFERROR((E3/D3),0) -> 0 | H3: =COUNTIFS(IH!M:M,B3,IH!T:T,"MSSF LOGIN") -> 0 | I3: =COUNTIFS(IH!M:M,B3,IH!T:T,"MSSF DISBURSED") -> 0 | J3: SALMAN | L3: COORDINATOR | M3: RETAIL | N3: IH Fin | O3: PENT% | P3: RETAIL | Q3: IH Fin | R3: PENT% | S3: RETAIL | T3: IH Fin | U3: PENT%
B4: ANGAMALY | C4: =COUNTIFS(Booking!C:C,B4) -> 17 | D4: =COUNTIFS(RETAIL!N:N,B4) -> 5 | E4: =COUNTIFS(IH!M:M,B4,IH!S:S,"DISBURSED") -> 4 | F4: =COUNTIFS(IH!M:M,B4,IH!S:S,"LOGIN") -> 3 | G4: =IFERROR((E4/D4),0) -> 0.8 | H4: =COUNTIFS(IH!M:M,B4,IH!T:T,"MSSF LOGIN") -> 5 | I4: =COUNTIFS(IH!M:M,B4,IH!T:T,"MSSF DISBURSED") -> 1 | J4: SALMAN | L4: SIVAPRASAD | M4: =COUNTIFS(RETAIL!X:X,L4) -> 48 | N4: =COUNTIFS(IH!S:S,"Disbursed",IH!U:U,L4) -> 28 | O4: =IFERROR((N4/M4),0) -> 0.58333333 | P4: =COUNTIFS([1]RETAIL!$X:$X,L4) -> 10 | Q4: =COUNTIFS([1]IH!$S:$S,"DISBURSED",[1]IH!$U:$U,L4) -> 7 | R4: =IFERROR((Q4/P4),0) -> 0.7 | S4: =M4+P4 -> 58 | T4: =N4+Q4 -> 35 | U4: =IFERROR((T4/S4),0) -> 0.60344828
B5: CHAVAKKAD | C5: =COUNTIFS(Booking!C:C,B5) -> 31 | D5: =COUNTIFS(RETAIL!N:N,B5) -> 9 | E5: =COUNTIFS(IH!M:M,B5,IH!S:S,"DISBURSED") -> 8 | F5: =COUNTIFS(IH!M:M,B5,IH!S:S,"LOGIN") -> 0 | G5: =IFERROR((E5/D5),0) -> 0.88888889 | H5: =COUNTIFS(IH!M:M,B5,IH!T:T,"MSSF LOGIN") -> 0 | I5: =COUNTIFS(IH!M:M,B5,IH!T:T,"MSSF DISBURSED") -> 4 | J5: SINTO | L5: AMAL | M5: =COUNTIFS(RETAIL!X:X,L5) -> 34 | N5: =COUNTIFS(IH!S:S,"Disbursed",IH!U:U,L5) -> 19 | O5: =IFERROR((N5/M5),0) -> 0.55882353 | P5: =COUNTIFS([1]RETAIL!$X:$X,L5) -> 5 | Q5: =COUNTIFS([1]IH!$S:$S,"DISBURSED",[1]IH!$U:$U,L5) -> 4 | R5: =IFERROR((Q5/P5),0) -> 0.8 | S5: =M5+P5 -> 39 | T5: =N5+Q5 -> 23 | U5: =IFERROR((T5/S5),0) -> 0.58974359
B6: EDAPPALLY | C6: =COUNTIFS(Booking!C:C,B6) -> 57 | D6: =COUNTIFS(RETAIL!N:N,B6) -> 35 | E6: =COUNTIFS(IH!M:M,B6,IH!S:S,"DISBURSED") -> 20 | F6: =COUNTIFS(IH!M:M,B6,IH!S:S,"LOGIN") -> 11 | G6: =IFERROR((E6/D6),0) -> 0.57142857 | H6: =COUNTIFS(IH!M:M,B6,IH!T:T,"MSSF LOGIN") -> 19 | I6: =COUNTIFS(IH!M:M,B6,IH!T:T,"MSSF DISBURSED") -> 11 | J6: SIVAPRASAD | L6: SALMAN | M6: =COUNTIFS(RETAIL!X:X,L6) -> 26 | N6: =COUNTIFS(IH!S:S,"Disbursed",IH!U:U,L6) -> 18 | O6: =IFERROR((N6/M6),0) -> 0.69230769 | P6: =COUNTIFS([1]RETAIL!$X:$X,L6) -> 9 | Q6: =COUNTIFS([1]IH!$S:$S,"DISBURSED",[1]IH!$U:$U,L6) -> 8 | R6: =IFERROR((Q6/P6),0) -> 0.88888889 | S6: =M6+P6 -> 35 | T6: =N6+Q6 -> 26 | U6: =IFERROR((T6/S6),0) -> 0.74285714
B7: FORTKOCHI | C7: =COUNTIFS(Booking!C:C,B7) -> 20 | D7: =COUNTIFS(RETAIL!N:N,B7) -> 4 | E7: =COUNTIFS(IH!M:M,B7,IH!S:S,"DISBURSED") -> 3 | F7: =COUNTIFS(IH!M:M,B7,IH!S:S,"LOGIN") -> 3 | G7: =IFERROR((E7/D7),0) -> 0.75 | H7: =COUNTIFS(IH!M:M,B7,IH!T:T,"MSSF LOGIN") -> 4 | I7: =COUNTIFS(IH!M:M,B7,IH!T:T,"MSSF DISBURSED") -> 2 | J7: SIVAPRASAD | L7: SINTO | M7: =COUNTIFS(RETAIL!X:X,L7) -> 34 | N7: =COUNTIFS(IH!S:S,"Disbursed",IH!U:U,L7) -> 20 | O7: =IFERROR((N7/M7),0) -> 0.58823529 | P7: =COUNTIFS([1]RETAIL!$X:$X,L7) -> 9 | Q7: =COUNTIFS([1]IH!$S:$S,"DISBURSED",[1]IH!$U:$U,L7) -> 6 | R7: =IFERROR((Q7/P7),0) -> 0.66666667 | S7: =M7+P7 -> 43 | T7: =N7+Q7 -> 26 | U7: =IFERROR((T7/S7),0) -> 0.60465116
B8: KADAVANTHRA | C8: =COUNTIFS(Booking!C:C,B8) -> 19 | D8: =COUNTIFS(RETAIL!N:N,B8) -> 8 | E8: =COUNTIFS(IH!M:M,B8,IH!S:S,"DISBURSED") -> 5 | F8: =COUNTIFS(IH!M:M,B8,IH!S:S,"LOGIN") -> 2 | G8: =IFERROR((E8/D8),0) -> 0.625 | H8: =COUNTIFS(IH!M:M,B8,IH!T:T,"MSSF LOGIN") -> 3 | I8: =COUNTIFS(IH!M:M,B8,IH!T:T,"MSSF DISBURSED") -> 4 | J8: SALMAN | L8: JINEESH | M8: =COUNTIFS(RETAIL!X:X,L8) -> 33 | N8: =COUNTIFS(IH!S:S,"Disbursed",IH!U:U,L8) -> 20 | O8: =IFERROR((N8/M8),0) -> 0.60606061 | P8: =COUNTIFS([1]RETAIL!$X:$X,L8) -> 22 | Q8: =COUNTIFS([1]IH!$S:$S,"DISBURSED",[1]IH!$U:$U,L8) -> 18 | R8: =IFERROR((Q8/P8),0) -> 0.81818182 | S8: =M8+P8 -> 55 | T8: =N8+Q8 -> 38 | U8: =IFERROR((T8/S8),0) -> 0.69090909
B9: KAIPAMANGALAM | C9: =COUNTIFS(Booking!C:C,B9) -> 33 | D9: =COUNTIFS(RETAIL!N:N,B9) -> 19 | E9: =COUNTIFS(IH!M:M,B9,IH!S:S,"DISBURSED") -> 11 | F9: =COUNTIFS(IH!M:M,B9,IH!S:S,"LOGIN") -> 0 | G9: =IFERROR((E9/D9),0) -> 0.57894737 | H9: =COUNTIFS(IH!M:M,B9,IH!T:T,"MSSF LOGIN") -> 1 | I9: =COUNTIFS(IH!M:M,B9,IH!T:T,"MSSF DISBURSED") -> 9 | J9: JINEESH | L9: WILSON | M9: =COUNTIFS(RETAIL!X:X,L9) -> 10 | N9: =COUNTIFS(IH!S:S,"Disbursed",IH!U:U,L9) -> 4 | O9: =IFERROR((N9/M9),0) -> 0.4 | P9: =COUNTIFS([1]RETAIL!$X:$X,L9) -> 70 | Q9: =COUNTIFS([1]IH!$S:$S,"DISBURSED",[1]IH!$U:$U,L9) -> 45 | R9: =IFERROR((Q9/P9),0) -> 0.64285714 | S9: =M9+P9 -> 80 | T9: =N9+Q9 -> 49 | U9: =IFERROR((T9/S9),0) -> 0.6125
B10: KODUNGALLUR | C10: =COUNTIFS(Booking!C:C,B10) -> 44 | D10: =COUNTIFS(RETAIL!N:N,B10) -> 13 | E10: =COUNTIFS(IH!M:M,B10,IH!S:S,"DISBURSED") -> 8 | F10: =COUNTIFS(IH!M:M,B10,IH!S:S,"LOGIN") -> 0 | G10: =IFERROR((E10/D10),0) -> 0.61538462 | H10: =COUNTIFS(IH!M:M,B10,IH!T:T,"MSSF LOGIN") -> 2 | I10: =COUNTIFS(IH!M:M,B10,IH!T:T,"MSSF DISBURSED") -> 3 | J10: JINEESH | L10: PRADEEP | M10: 0 | N10: 0 | O10: =IFERROR((N10/M10),0) -> 0 | P10: 0 | Q10: 0 | R10: =IFERROR((Q10/P10),0) -> 0 | S10: =M10+P10 -> 0 | T10: =N10+Q10 -> 0 | U10: =IFERROR((T10/S10),0) -> 0
B11: KOLENCHERY | C11: =COUNTIFS(Booking!C:C,B11) -> 25 | D11: =COUNTIFS(RETAIL!N:N,B11) -> 9 | E11: =COUNTIFS(IH!M:M,B11,IH!S:S,"DISBURSED") -> 7 | F11: =COUNTIFS(IH!M:M,B11,IH!S:S,"LOGIN") -> 1 | G11: =IFERROR((E11/D11),0) -> 0.77777778 | H11: =COUNTIFS(IH!M:M,B11,IH!T:T,"MSSF LOGIN") -> 1 | I11: =COUNTIFS(IH!M:M,B11,IH!T:T,"MSSF DISBURSED") -> 4 | J11: AMAL | L11: ABHIJITH | M11: 0 | N11: 0 | O11: =IFERROR((N11/M11),0) -> 0 | P11: 0 | Q11: 0 | R11: =IFERROR((Q11/P11),0) -> 0 | S11: =M11+P11 -> 0 | T11: =N11+Q11 -> 0 | U11: =IFERROR((T11/S11),0) -> 0
B12: KOOTHATTUKULAM | C12: =COUNTIFS(Booking!C:C,B12) -> 29 | D12: =COUNTIFS(RETAIL!N:N,B12) -> 11 | E12: =COUNTIFS(IH!M:M,B12,IH!S:S,"DISBURSED") -> 6 | F12: =COUNTIFS(IH!M:M,B12,IH!S:S,"LOGIN") -> 1 | G12: =IFERROR((E12/D12),0) -> 0.54545455 | H12: =COUNTIFS(IH!M:M,B12,IH!T:T,"MSSF LOGIN") -> 3 | I12: =COUNTIFS(IH!M:M,B12,IH!T:T,"MSSF DISBURSED") -> 2 | J12: AMAL | L12: ALFY | M12: 0 | N12: 0 | O12: =IFERROR((N12/M12),0) -> 0 | P12: 0 | Q12: 0 | R12: =IFERROR((Q12/P12),0) -> 0 | S12: =M12+P12 -> 0 | T12: =N12+Q12 -> 0 | U12: =IFERROR((T12/S12),0) -> 0
B13: PERUMBAVOOR | C13: =COUNTIFS(Booking!C:C,B13) -> 25 | D13: =COUNTIFS(RETAIL!N:N,B13) -> 12 | E13: =COUNTIFS(IH!M:M,B13,IH!S:S,"DISBURSED") -> 9 | F13: =COUNTIFS(IH!M:M,B13,IH!S:S,"LOGIN") -> 1 | G13: =IFERROR((E13/D13),0) -> 0.75 | H13: =COUNTIFS(IH!M:M,B13,IH!T:T,"MSSF LOGIN") -> 2 | I13: =COUNTIFS(IH!M:M,B13,IH!T:T,"MSSF DISBURSED") -> 7 | J13: SALMAN | L13: TOTAL | M13: =SUM(M4:M12) -> 185 | N13: =SUM(N4:N12) -> 109 | O13: =IFERROR((N13/M13),0) -> 0.58918919 | P13: =SUM(P4:P12) -> 125 | Q13: =SUM(Q4:Q12) -> 88 | R13: =IFERROR((Q13/P13),0) -> 0.704 | S13: =SUM(S4:S12) -> 310 | T13: =SUM(T4:T12) -> 197 | U13: =IFERROR((T13/S13),0) -> 0.63548387
B14: PIRAVOM | C14: =COUNTIFS(Booking!C:C,B14) -> 23 | D14: =COUNTIFS(RETAIL!N:N,B14) -> 14 | E14: =COUNTIFS(IH!M:M,B14,IH!S:S,"DISBURSED") -> 6 | F14: =COUNTIFS(IH!M:M,B14,IH!S:S,"LOGIN") -> 0 | G14: =IFERROR((E14/D14),0) -> 0.42857143 | H14: =COUNTIFS(IH!M:M,B14,IH!T:T,"MSSF LOGIN") -> 1 | I14: =COUNTIFS(IH!M:M,B14,IH!T:T,"MSSF DISBURSED") -> 3 | J14: AMAL | L14: ARENA COCHIN | M14: ='Arena+Nexa'!C24 -> 174 | N14: ='Arena+Nexa'!F24 -> 104 | O14: =IFERROR((N14/M14),0) -> 0.59770115 | P14: ='Arena+Nexa'!D24 -> 49 | Q14: ='Arena+Nexa'!G24 -> 38 | R14: =IFERROR((Q14/P14),0) -> 0.7755102 | S14: =M14+P14 -> 223 | T14: =N14+Q14 -> 142 | U14: =IFERROR((T14/S14),0) -> 0.6367713
B15: THRISSUR | C15: =COUNTIFS(Booking!C:C,B15) -> 36 | D15: =COUNTIFS(RETAIL!N:N,B15) -> 25 | E15: =COUNTIFS(IH!M:M,B15,IH!S:S,"DISBURSED") -> 12 | F15: =COUNTIFS(IH!M:M,B15,IH!S:S,"LOGIN") -> 0 | G15: =IFERROR((E15/D15),0) -> 0.48 | H15: =COUNTIFS(IH!M:M,B15,IH!T:T,"MSSF LOGIN") -> 1 | I15: =COUNTIFS(IH!M:M,B15,IH!T:T,"MSSF DISBURSED") -> 5 | J15: SINTO
B16: TRIPPUNITHURA | C16: =COUNTIFS(Booking!C:C,B16) -> 16 | D16: =COUNTIFS(RETAIL!N:N,B16) -> 9 | E16: =COUNTIFS(IH!M:M,B16,IH!S:S,"DISBURSED") -> 5 | F16: =COUNTIFS(IH!M:M,B16,IH!S:S,"LOGIN") -> 0 | G16: =IFERROR((E16/D16),0) -> 0.55555556 | H16: =COUNTIFS(IH!M:M,B16,IH!T:T,"MSSF LOGIN") -> 4 | I16: =COUNTIFS(IH!M:M,B16,IH!T:T,"MSSF DISBURSED") -> 1 | J16: SIVAPRASAD
B17: NEXA COCHIN | C17: =COUNTIFS(Booking!C:C,B17) -> 16 | D17: =COUNTIFS(RETAIL!N:N,B17) -> 10 | E17: =COUNTIFS(IH!M:M,B17,IH!S:S,"DISBURSED") -> 4 | F17: =COUNTIFS(IH!M:M,B17,IH!S:S,"LOGIN") -> 0 | G17: =IFERROR((E17/D17),0) -> 0.4 | H17: =COUNTIFS(IH!M:M,B17,IH!T:T,"MSSF LOGIN") -> 2 | I17: =COUNTIFS(IH!M:M,B17,IH!T:T,"MSSF DISBURSED") -> 2 | J17: WILSON
B18: STUDIO KDLR | C18: =COUNTIFS(Booking!C:C,B18) -> 0 | D18: =COUNTIFS(RETAIL!N:N,B18) -> 1 | E18: =COUNTIFS(IH!M:M,B18,IH!S:S,"DISBURSED") -> 1 | F18: =COUNTIFS(IH!M:M,B18,IH!S:S,"LOGIN") -> 0 | G18: =IFERROR((E18/D18),0) -> 1 | H18: =COUNTIFS(IH!M:M,B18,IH!T:T,"MSSF LOGIN") -> 0 | I18: =COUNTIFS(IH!M:M,B18,IH!T:T,"MSSF DISBURSED") -> 1 | J18: JINEESH
B19: STUDIO KPLM | C19: =COUNTIFS(Booking!C:C,B19) -> 0 | D19: =COUNTIFS(RETAIL!N:N,B19) -> 0 | E19: =COUNTIFS(IH!M:M,B19,IH!S:S,"DISBURSED") -> 0 | F19: =COUNTIFS(IH!M:M,B19,IH!S:S,"LOGIN") -> 0 | G19: =IFERROR((E19/D19),0) -> 0 | H19: =COUNTIFS(IH!M:M,B19,IH!T:T,"MSSF LOGIN") -> 0 | I19: =COUNTIFS(IH!M:M,B19,IH!T:T,"MSSF DISBURSED") -> 0 | J19: JINEESH
B20: Total | C20: =SUM(C3:C19) -> 396 | D20: =SUM(D3:D19) -> 185 | E20: =SUM(E3:E19) -> 109 | F20: =SUM(F3:F19) -> 22 | G20: =IFERROR((E20/D20),0) -> 0.58918919 | H20: =SUM(H3:H19) -> 48 | I20: =SUM(I3:I19) -> 59 | J20: =IFERROR((I20/D20),0) -> 0.31891892
B22: ARENA | C22: =SUM(C3:C16) -> 380 | D22: =SUM(D3:D16) -> 174 | E22: =SUM(E3:E16) -> 104 | F22: =SUM(F3:F16) -> 22 | G22: =IFERROR((E22/D22),0) -> 0.59770115 | H22: =SUM(H3:H16) -> 46 | I22: =SUM(I3:I16) -> 56
B23: NEXA | C23: =C17 -> 16 | D23: =D17 -> 10 | E23: =E17 -> 4 | F23: =F17 -> 0 | G23: =IFERROR((E23/D23),0) -> 0.4 | H23: =H17 -> 2 | I23: =I17 -> 2
B24: STUDIO | C24: =SUM(C18:C19) -> 0 | D24: =SUM(D18:D19) -> 1 | E24: =SUM(E18:E19) -> 1 | F24: =SUM(F18:F19) -> 0 | G24: =IFERROR((E24/D24),0) -> 1 | H24: =SUM(H18:H19) -> 0 | I24: =SUM(I18:I19) -> 1
C26: Date | D26: Retail | E26: IH | F26: Pent % | H26: MF | I26: MF %
C27: 46109 | D27: 10 | E27: =COUNTIFS(IH!P:P,C27) -> 9 | F27: =IFERROR((E27/D27),0) -> 0.9 | H27: =E27 -> 9 | I27: =H27/D27 -> 0.9
H28: =E20 -> 109 | I28: =G20 -> 0.58918919

Sheet Finance
B1: =CONCATENATE("IH Finance Performance Report as on ",TEXT(TODAY(),"dd-mmm-yy")) -> IH Finance Performance Report as on 30-Mar-26 | L1: =CONCATENATE("Arena Location wise IH Finance Performance as on ",TEXT(TODAY(),"dd-mmm-yy")) -> Arena Location wise IH Finance Performance as on 30-Mar-26
B2: Channel/Location | C2: ARENA | F2: NEXA | J2: GRAND TOTAL | L2: OUTLET | M2: Booking | N2: Bkg IH | O2: Retail | P2: IH | Q2: Pent % | R2: Login | S2: Allot | T2: Allot IH
C3: COCHIN | D3: CGR | E3: TOTAL | F3: COCHIN | G3: KYM | H3: KTM | I3: TOTAL | L3: ALUVA | M3: =COUNTIFS(Booking!C:C,L3) -> 5 | N3: =COUNTIFS(Booking!E:E,"IH",Booking!C:C,L3) -> 0 | O3: =COUNTIFS(RETAIL!N:N,+L3) -> 1 | P3: =COUNTIFS(IH!M:M,L3,IH!S:S,"DISBURSED") -> 0 | Q3: =IFERROR((P3/O3),0) -> 0 | R3: =COUNTIFS(IH!M:M,L3,IH!S:S,"LOGIN") -> 0 | S3: =COUNTIFS(Allotment!D:D,L3) -> 0 | T3: =COUNTIFS(Allotment!F:F,"IH",Allotment!D:D,L3) -> 0
B4: RETAIL | C4: =O20 -> 185 | D4: 46 | E4: =C4+D4 -> 231 | F4: =[1]SRM!$D$10 -> 125 | G4: 51 | H4: 62 | I4: =F4+G4+H4 -> 238 | J4: =E4+I4 -> 469 | L4: ANGAMALY | M4: =COUNTIFS(Booking!C:C,L4) -> 17 | N4: =COUNTIFS(Booking!E:E,"IH",Booking!C:C,L4) -> 7 | O4: =COUNTIFS(RETAIL!N:N,+L4) -> 5 | P4: =COUNTIFS(IH!M:M,L4,IH!S:S,"DISBURSED") -> 4 | Q4: =IFERROR((P4/O4),0) -> 0.8 | R4: =COUNTIFS(IH!M:M,L4,IH!S:S,"LOGIN") -> 3 | S4: =COUNTIFS(Allotment!D:D,L4) -> 0 | T4: =COUNTIFS(Allotment!F:F,"IH",Allotment!D:D,L4) -> 0
B5: IN FIN | C5: =P20 -> 109 | D5: 18 | E5: =C5+D5 -> 127 | F5: =[1]SRM!$E$10 -> 88 | G5: 38 | H5: 38 | I5: =F5+G5+H5 -> 164 | J5: =E5+I5 -> 291 | L5: CHAVAKKAD | M5: =COUNTIFS(Booking!C:C,L5) -> 31 | N5: =COUNTIFS(Booking!E:E,"IH",Booking!C:C,L5) -> 15 | O5: =COUNTIFS(RETAIL!N:N,+L5) -> 9 | P5: =COUNTIFS(IH!M:M,L5,IH!S:S,"DISBURSED") -> 8 | Q5: =IFERROR((P5/O5),0) -> 0.88888889 | R5: =COUNTIFS(IH!M:M,L5,IH!S:S,"LOGIN") -> 0 | S5: =COUNTIFS(Allotment!D:D,L5) -> 2 | T5: =COUNTIFS(Allotment!F:F,"IH",Allotment!D:D,L5) -> 2
B6: IH FIN AMT (Lac) | C6: =D25 -> 646.93841 | D6: 134.61 | E6: =C6+D6 -> 781.54841 | F6: =[1]SRM!$C$17 -> 604.21806 | G6: 280.89 | H6: 252.43 | I6: =F6+G6+H6 -> 1137.5381 | J6: =E6+I6 -> 1919.0865 | L6: EDAPPALLY | M6: =COUNTIFS(Booking!C:C,L6) -> 57 | N6: =COUNTIFS(Booking!E:E,"IH",Booking!C:C,L6) -> 34 | O6: =COUNTIFS(RETAIL!N:N,+L6) -> 35 | P6: =COUNTIFS(IH!M:M,L6,IH!S:S,"DISBURSED") -> 20 | Q6: =IFERROR((P6/O6),0) -> 0.57142857 | R6: =COUNTIFS(IH!M:M,L6,IH!S:S,"LOGIN") -> 11 | S6: =COUNTIFS(Allotment!D:D,L6) -> 21 | T6: =COUNTIFS(Allotment!F:F,"IH",Allotment!D:D,L6) -> 7
B7: IH PENT % | C7: =IFERROR((C5/C4),0) -> 0.58918919 | D7: =IFERROR((D5/D4),0) -> 0.39130435 | E7: =IFERROR((E5/E4),0) -> 0.54978355 | F7: =IFERROR((F5/F4),0) -> 0.704 | G7: =IFERROR((G5/G4),0) -> 0.74509804 | H7: =IFERROR((H5/H4),0) -> 0.61290323 | I7: =IFERROR((I5/I4),0) -> 0.68907563 | J7: =IFERROR((J5/J4),0) -> 0.62046908 | L7: FORTKOCHI | M7: =COUNTIFS(Booking!C:C,L7) -> 20 | N7: =COUNTIFS(Booking!E:E,"IH",Booking!C:C,L7) -> 8 | O7: =COUNTIFS(RETAIL!N:N,+L7) -> 4 | P7: =COUNTIFS(IH!M:M,L7,IH!S:S,"DISBURSED") -> 3 | Q7: =IFERROR((P7/O7),0) -> 0.75 | R7: =COUNTIFS(IH!M:M,L7,IH!S:S,"LOGIN") -> 3 | S7: =COUNTIFS(Allotment!D:D,L7) -> 3 | T7: =COUNTIFS(Allotment!F:F,"IH",Allotment!D:D,L7) -> 2
B8: BOOKING | C8: =Report!F10 -> 396 | D8: 115 | E8: =C8+D8 -> 511 | F8: =[1]Report!$M$17 -> 189 | G8: 128 | H8: 130 | I8: =F8+G8+H8 -> 447 | J8: =E8+I8 -> 958 | L8: KADAVANTHRA | M8: =COUNTIFS(Booking!C:C,L8) -> 19 | N8: =COUNTIFS(Booking!E:E,"IH",Booking!C:C,L8) -> 6 | O8: =COUNTIFS(RETAIL!N:N,+L8) -> 8 | P8: =COUNTIFS(IH!M:M,L8,IH!S:S,"DISBURSED") -> 5 | Q8: =IFERROR((P8/O8),0) -> 0.625 | R8: =COUNTIFS(IH!M:M,L8,IH!S:S,"LOGIN") -> 2 | S8: =COUNTIFS(Allotment!D:D,L8) -> 3 | T8: =COUNTIFS(Allotment!F:F,"IH",Allotment!D:D,L8) -> 2
B9: LOGIN | C9: =Report!H10 -> 79 | D9: 20 | E9: =C9+D9 -> 99 | F9: =[1]Report!$N$17 -> 32 | G9: 10 | H9: 11 | I9: =F9+G9+H9 -> 53 | J9: =E9+I9 -> 152 | L9: KAIPAMANGALAM | M9: =COUNTIFS(Booking!C:C,L9) -> 33 | N9: =COUNTIFS(Booking!E:E,"IH",Booking!C:C,L9) -> 15 | O9: =COUNTIFS(RETAIL!N:N,+L9) -> 19 | P9: =COUNTIFS(IH!M:M,L9,IH!S:S,"DISBURSED") -> 11 | Q9: =IFERROR((P9/O9),0) -> 0.57894737 | R9: =COUNTIFS(IH!M:M,L9,IH!S:S,"LOGIN") -> 0 | S9: =COUNTIFS(Allotment!D:D,L9) -> 6 | T9: =COUNTIFS(Allotment!F:F,"IH",Allotment!D:D,L9) -> 4
B10: PEND. LOGIN | C10: =Report!J10 -> 95 | D10: 62 | E10: =C10+D10 -> 157 | F10: =[1]Report!$O$17 -> 28 | G10: 36 | H10: 19 | I10: =F10+G10+H10 -> 83 | J10: =E10+I10 -> 240 | L10: KODUNGALLUR | M10: =COUNTIFS(Booking!C:C,L10) -> 44 | N10: =COUNTIFS(Booking!E:E,"IH",Booking!C:C,L10) -> 16 | O10: =COUNTIFS(RETAIL!N:N,+L10) -> 13 | P10: =COUNTIFS(IH!M:M,L10,IH!S:S,"DISBURSED") -> 8 | Q10: =IFERROR((P10/O10),0) -> 0.61538462 | R10: =COUNTIFS(IH!M:M,L10,IH!S:S,"LOGIN") -> 0 | S10: =COUNTIFS(Allotment!D:D,L10) -> 8 | T10: =COUNTIFS(Allotment!F:F,"IH",Allotment!D:D,L10) -> 3
B11: BOOKING % | C11: =IFERROR((C9/C8),0) -> 0.19949495 | D11: =IFERROR((D9/D8),0) -> 0.17391304 | E11: =IFERROR((E9/E8),0) -> 0.19373777 | F11: =IFERROR((F9/F8),0) -> 0.16931217 | G11: =IFERROR((G9/G8),0) -> 0.078125 | H11: =IFERROR((H9/H8),0) -> 0.084615385 | I11: =IFERROR((I9/I8),0) -> 0.11856823 | J11: =IFERROR((J9/J8),0) -> 0.15866388 | L11: KOLENCHERY | M11: =COUNTIFS(Booking!C:C,L11) -> 25 | N11: =COUNTIFS(Booking!E:E,"IH",Booking!C:C,L11) -> 12 | O11: =COUNTIFS(RETAIL!N:N,+L11) -> 9 | P11: =COUNTIFS(IH!M:M,L11,IH!S:S,"DISBURSED") -> 7 | Q11: =IFERROR((P11/O11),0) -> 0.77777778 | R11: =COUNTIFS(IH!M:M,L11,IH!S:S,"LOGIN") -> 1 | S11: =COUNTIFS(Allotment!D:D,L11) -> 1 | T11: =COUNTIFS(Allotment!F:F,"IH",Allotment!D:D,L11) -> 1
B12: ALLOTMENTS | C12: =S20 -> 71 | D12: 15 | E12: =C12+D12 -> 86 | F12: =[1]SRM!$U$24 -> 29 | G12: 10 | H12: 13 | I12: =F12+G12+H12 -> 52 | J12: =E12+I12 -> 138 | L12: KOOTHATTUKULAM | M12: =COUNTIFS(Booking!C:C,L12) -> 29 | N12: =COUNTIFS(Booking!E:E,"IH",Booking!C:C,L12) -> 9 | O12: =COUNTIFS(RETAIL!N:N,+L12) -> 11 | P12: =COUNTIFS(IH!M:M,L12,IH!S:S,"DISBURSED") -> 6 | Q12: =IFERROR((P12/O12),0) -> 0.54545455 | R12: =COUNTIFS(IH!M:M,L12,IH!S:S,"LOGIN") -> 1 | S12: =COUNTIFS(Allotment!D:D,L12) -> 5 | T12: =COUNTIFS(Allotment!F:F,"IH",Allotment!D:D,L12) -> 2
B13: ALLOT - IH | C13: =T20 -> 32 | D13: 9 | E13: =C13+D13 -> 41 | F13: =[1]SRM!$V$24 -> 18 | G13: 4 | H13: 7 | I13: =F13+G13+H13 -> 29 | J13: =E13+I13 -> 70 | L13: NEXA COCHIN | M13: =COUNTIFS(Booking!C:C,L13) -> 16 | N13: =COUNTIFS(Booking!E:E,"IH",Booking!C:C,L13) -> 5 | O13: =COUNTIFS(RETAIL!N:N,+L13) -> 10 | P13: =COUNTIFS(IH!M:M,L13,IH!S:S,"DISBURSED") -> 4 | Q13: =IFERROR((P13/O13),0) -> 0.4 | R13: =COUNTIFS(IH!M:M,L13,IH!S:S,"LOGIN") -> 0 | S13: =COUNTIFS(Allotment!D:D,L13) -> 7 | T13: =COUNTIFS(Allotment!F:F,"IH",Allotment!D:D,L13) -> 0
B14: ALLOTMENT - IH % | C14: =IFERROR((C13/C12),0) -> 0.45070423 | D14: =IFERROR((D13/D12),0) -> 0.6 | E14: =IFERROR((E13/E12),0) -> 0.47674419 | F14: =IFERROR((F13/F12),0) -> 0.62068966 | G14: =IFERROR((G13/G12),0) -> 0.4 | H14: =IFERROR((H13/H12),0) -> 0.53846154 | I14: =IFERROR((I13/I12),0) -> 0.55769231 | J14: =IFERROR((J13/J12),0) -> 0.50724638 | L14: PERUMBAVOOR | M14: =COUNTIFS(Booking!C:C,L14) -> 25 | N14: =COUNTIFS(Booking!E:E,"IH",Booking!C:C,L14) -> 10 | O14: =COUNTIFS(RETAIL!N:N,+L14) -> 12 | P14: =COUNTIFS(IH!M:M,L14,IH!S:S,"DISBURSED") -> 9 | Q14: =IFERROR((P14/O14),0) -> 0.75 | R14: =COUNTIFS(IH!M:M,L14,IH!S:S,"LOGIN") -> 1 | S14: =COUNTIFS(Allotment!D:D,L14) -> 4 | T14: =COUNTIFS(Allotment!F:F,"IH",Allotment!D:D,L14) -> 2
B15: RIPS | C15: =C4 -> 185 | D15: =D4 -> 46 | E15: =C15+D15 -> 231 | F15: =F4 -> 125 | G15: =G4 -> 51 | H15: =H4 -> 62 | I15: =F15+G15+H15 -> 238 | J15: =E15+I15 -> 469 | L15: PIRAVOM | M15: =COUNTIFS(Booking!C:C,L15) -> 23 | N15: =COUNTIFS(Booking!E:E,"IH",Booking!C:C,L15) -> 8 | O15: =COUNTIFS(RETAIL!N:N,+L15) -> 14 | P15: =COUNTIFS(IH!M:M,L15,IH!S:S,"DISBURSED") -> 6 | Q15: =IFERROR((P15/O15),0) -> 0.42857143 | R15: =COUNTIFS(IH!M:M,L15,IH!S:S,"LOGIN") -> 0 | S15: =COUNTIFS(Allotment!D:D,L15) -> 2 | T15: =COUNTIFS(Allotment!F:F,"IH",Allotment!D:D,L15) -> 2
B16: MSSF | C16: =Outlet!I20 -> 59 | D16: 13 | E16: =C16+D16 -> 72 | F16: =[1]SRM!$K$10 -> 61 | G16: 34 | H16: 33 | I16: =F16+G16+H16 -> 128 | J16: =E16+I16 -> 200 | L16: THRISSUR | M16: =COUNTIFS(Booking!C:C,L16) -> 36 | N16: =COUNTIFS(Booking!E:E,"IH",Booking!C:C,L16) -> 20 | O16: =COUNTIFS(RETAIL!N:N,+L16) -> 25 | P16: =COUNTIFS(IH!M:M,L16,IH!S:S,"DISBURSED") -> 12 | Q16: =IFERROR((P16/O16),0) -> 0.48 | R16: =COUNTIFS(IH!M:M,L16,IH!S:S,"LOGIN") -> 0 | S16: =COUNTIFS(Allotment!D:D,L16) -> 4 | T16: =COUNTIFS(Allotment!F:F,"IH",Allotment!D:D,L16) -> 2
B17: MSSF% | C17: =IFERROR((C16/C15),0) -> 0.31891892 | D17: =IFERROR((D16/D15),0) -> 0.2826087 | E17: =IFERROR((E16/E15),0) -> 0.31168831 | F17: =IFERROR((F16/F15),0) -> 0.488 | G17: =IFERROR((G16/G15),0) -> 0.66666667 | H17: =IFERROR((H16/H15),0) -> 0.53225806 | I17: =IFERROR((I16/I15),0) -> 0.53781513 | J17: =IFERROR((J16/J15),0) -> 0.42643923 | L17: TRIPPUNITHURA | M17: =COUNTIFS(Booking!C:C,L17) -> 16 | N17: =COUNTIFS(Booking!E:E,"IH",Booking!C:C,L17) -> 9 | O17: =COUNTIFS(RETAIL!N:N,+L17) -> 9 | P17: =COUNTIFS(IH!M:M,L17,IH!S:S,"DISBURSED") -> 5 | Q17: =IFERROR((P17/O17),0) -> 0.55555556 | R17: =COUNTIFS(IH!M:M,L17,IH!S:S,"LOGIN") -> 0 | S17: =COUNTIFS(Allotment!D:D,L17) -> 4 | T17: =COUNTIFS(Allotment!F:F,"IH",Allotment!D:D,L17) -> 3
L18: STUDIO KDLR | M18: =COUNTIFS(Booking!C:C,L18) -> 0 | N18: =COUNTIFS(Booking!E:E,"IH",Booking!C:C,L18) -> 0 | O18: =COUNTIFS(RETAIL!N:N,+L18) -> 1 | P18: =COUNTIFS(IH!M:M,L18,IH!S:S,"DISBURSED") -> 1 | Q18: =IFERROR((P18/O18),0) -> 1 | R18: =COUNTIFS(IH!M:M,L18,IH!S:S,"LOGIN") -> 0 | S18: =COUNTIFS(Allotment!D:D,L18) -> 1 | T18: =COUNTIFS(Allotment!F:F,"IH",Allotment!D:D,L18) -> 0
L19: STUDIO KPLM | M19: =COUNTIFS(Booking!C:C,L19) -> 0 | N19: =COUNTIFS(Booking!E:E,"IH",Booking!C:C,L19) -> 0 | O19: =COUNTIFS(RETAIL!N:N,+L19) -> 0 | P19: =COUNTIFS(IH!M:M,L19,IH!S:S,"DISBURSED") -> 0 | Q19: =IFERROR((P19/O19),0) -> 0 | R19: =COUNTIFS(IH!M:M,L19,IH!S:S,"LOGIN") -> 0 | S19: =COUNTIFS(Allotment!D:D,L19) -> 0 | T19: =COUNTIFS(Allotment!F:F,"IH",Allotment!D:D,L19) -> 0
L20: TOTAL | M20: =SUM(M3:M19) -> 396 | N20: =SUM(N3:N19) -> 174 | O20: =SUM(O3:O19) -> 185 | P20: =SUM(P3:P19) -> 109 | Q20: =IFERROR((P20/O20),0) -> 0.58918919 | R20: =SUM(R3:R19) -> 22 | S20: =SUM(S3:S19) -> 71 | T20: =SUM(T3:T19) -> 32
B21: =CONCATENATE("Arena Report ",TEXT(TODAY(),"dd-mmm-yy")) -> Arena Report 30-Mar-26
B22: Today Login - | C22: =COUNTIFS(IH!O:O,TODAY()) -> 1 | D22: =C22*4 -> 4
B23: Total Login - | C23: =Outlet!F20 -> 22 | D23: =C23*4 -> 88
B24: Today Disb - | C24: =COUNTIFS(IH!P:P,TODAY()) -> 3 | D24: =SUMIFS(IH!H:H,IH!S:S,"DISBURSED",IH!P:P,TODAY())/100000 -> 14.23865
B25: Total Disb - | C25: =Outlet!E20 -> 109 | D25: =SUMIFS(IH!H:H,IH!S:S,"Disbursed")/100000 -> 646.93841
B26: Retail - | C26: =Outlet!D20 -> 185
B27: PENT% - | C27: =IFERROR((C25/C26),0) -> 0.58918919
B28: MSSFLogin - | C28: =Outlet!H20 -> 48
B29: MSSF Disb - | C29: =Outlet!I20 -> 59
B30: PENT% - | C30: =C29/C26 -> 0.31891892

Sheet Arena+Nexa
B1: Arena + Nexa Outletwise Performance - Mar-26 | P1: Arena + Nexa Outletwise Performance - Feb-26
C2: RETAIL | F2: IH FINANCE | I2: IH PENT% | Q2: RETAIL | T2: IH FINANCE | W2: IH PENT%
B3: LOCATION | C3: ARENA | D3: NEXA | E3: TOTAL | F3: ARENA | G3: NEXA | H3: TOTAL | I3: ARENA | J3: NEXA | K3: TOTAL | L3: CORDINATOR | M3: LOC | N3: TOUR | P3: LOCATION | Q3: ARENA | R3: NEXA | S3: TOTAL | T3: ARENA | U3: NEXA | V3: TOTAL | W3: ARENA | X3: NEXA | Y3: TOTAL
B4: ALUVA | C4: =COUNTIFS(RETAIL!N:N,B4) -> 1 | D4: =COUNTIFS([1]RETAIL!$N:$N,B4) -> 0 | E4: =C4+D4 -> 1 | F4: =COUNTIFS(IH!M:M,B4,IH!S:S,"DISBURSED") -> 0 | G4: =COUNTIFS([1]IH!$S:$S,"DISBURSED",[1]IH!$M:$M,B4) -> 0 | H4: =F4+G4 -> 0 | I4: =IFERROR((F4/C4),0) -> 0 | J4: =IFERROR((G4/D4),0) -> 0 | K4: =IFERROR((H4/E4),0) -> 0 | L4: SALMAN | M4: ARENA | N4: =COUNTIFS(RETAIL!K:K,"*TOUR*",RETAIL!N:N,B4) -> 0 | P4: ALUVA | Q4: 2 | R4: 1 | S4: =Q4+R4 -> 3 | T4: 1 | U4: 1 | V4: =T4+U4 -> 2 | W4: =IFERROR((T4/Q4),0) -> 0.5 | X4: =IFERROR((U4/R4),0) -> 1 | Y4: =IFERROR((V4/S4),0) -> 0.66666667
B5: ANGAMALY | C5: =COUNTIFS(RETAIL!N:N,B5) -> 5 | D5: =COUNTIFS([1]RETAIL!$N:$N,B5) -> 2 | E5: =C5+D5 -> 7 | F5: =COUNTIFS(IH!M:M,B5,IH!S:S,"DISBURSED") -> 4 | G5: =COUNTIFS([1]IH!$S:$S,"DISBURSED",[1]IH!$M:$M,B5) -> 2 | H5: =F5+G5 -> 6 | I5: =IFERROR((F5/C5),0) -> 0.8 | J5: =IFERROR((G5/D5),0) -> 1 | K5: =IFERROR((H5/E5),0) -> 0.85714286 | L5: SALMAN | M5: ARENA | N5: =COUNTIFS(RETAIL!K:K,"*TOUR*",RETAIL!N:N,B5) -> 2 | P5: ANGAMALY | Q5: 2 | R5: 0 | S5: =Q5+R5 -> 2 | T5: 0 | U5: 0 | V5: =T5+U5 -> 0 | W5: =IFERROR((T5/Q5),0) -> 0 | X5: =IFERROR((U5/R5),0) -> 0 | Y5: =IFERROR((V5/S5),0) -> 0
B6: CHAVAKKAD | C6: =COUNTIFS(RETAIL!N:N,B6) -> 9 | D6: =COUNTIFS([1]RETAIL!$N:$N,B6) -> 5 | E6: =C6+D6 -> 14 | F6: =COUNTIFS(IH!M:M,B6,IH!S:S,"DISBURSED") -> 8 | G6: =COUNTIFS([1]IH!$S:$S,"DISBURSED",[1]IH!$M:$M,B6) -> 3 | H6: =F6+G6 -> 11 | I6: =IFERROR((F6/C6),0) -> 0.88888889 | J6: =IFERROR((G6/D6),0) -> 0.6 | K6: =IFERROR((H6/E6),0) -> 0.78571429 | L6: SINTO | M6: STUDIO | N6: =COUNTIFS(RETAIL!K:K,"*TOUR*",RETAIL!N:N,B6) -> 2 | P6: CHAVAKKAD | Q6: 17 | R6: 3 | S6: =Q6+R6 -> 20 | T6: 7 | U6: 4 | V6: =T6+U6 -> 11 | W6: =IFERROR((T6/Q6),0) -> 0.41176471 | X6: =IFERROR((U6/R6),0) -> 1.3333333 | Y6: =IFERROR((V6/S6),0) -> 0.55
B7: EDAPPALLY | C7: =COUNTIFS(RETAIL!N:N,B7) -> 35 | D7: =COUNTIFS([1]RETAIL!$N:$N,B7) -> 7 | E7: =C7+D7 -> 42 | F7: =COUNTIFS(IH!M:M,B7,IH!S:S,"DISBURSED") -> 20 | G7: =COUNTIFS([1]IH!$S:$S,"DISBURSED",[1]IH!$M:$M,B7) -> 5 | H7: =F7+G7 -> 25 | I7: =IFERROR((F7/C7),0) -> 0.57142857 | J7: =IFERROR((G7/D7),0) -> 0.71428571 | K7: =IFERROR((H7/E7),0) -> 0.5952381 | L7: SIVAPRASAD | M7: ARENA | N7: =COUNTIFS(RETAIL!K:K,"*TOUR*",RETAIL!N:N,B7) -> 24 | P7: EDAPPALLY | Q7: 48 | R7: 3 | S7: =Q7+R7 -> 51 | T7: 30 | U7: 2 | V7: =T7+U7 -> 32 | W7: =IFERROR((T7/Q7),0) -> 0.625 | X7: =IFERROR((U7/R7),0) -> 0.66666667 | Y7: =IFERROR((V7/S7),0) -> 0.62745098
B8: FORTKOCHI | C8: =COUNTIFS(RETAIL!N:N,B8) -> 4 | D8: =COUNTIFS([1]RETAIL!$N:$N,B8) -> 1 | E8: =C8+D8 -> 5 | F8: =COUNTIFS(IH!M:M,B8,IH!S:S,"DISBURSED") -> 3 | G8: =COUNTIFS([1]IH!$S:$S,"DISBURSED",[1]IH!$M:$M,B8) -> 1 | H8: =F8+G8 -> 4 | I8: =IFERROR((F8/C8),0) -> 0.75 | J8: =IFERROR((G8/D8),0) -> 1 | K8: =IFERROR((H8/E8),0) -> 0.8 | L8: SIVAPRASAD | M8: ARENA | N8: =COUNTIFS(RETAIL!K:K,"*TOUR*",RETAIL!N:N,B8) -> 4 | P8: FORTKOCHI | Q8: 6 | R8: 2 | S8: =Q8+R8 -> 8 | T8: 4 | U8: 2 | V8: =T8+U8 -> 6 | W8: =IFERROR((T8/Q8),0) -> 0.66666667 | X8: =IFERROR((U8/R8),0) -> 1 | Y8: =IFERROR((V8/S8),0) -> 0.75
B9: KADAVANTHRA | C9: =COUNTIFS(RETAIL!N:N,B9) -> 8 | D9: =COUNTIFS([1]RETAIL!$N:$N,B9) -> 3 | E9: =C9+D9 -> 11 | F9: =COUNTIFS(IH!M:M,B9,IH!S:S,"DISBURSED") -> 5 | G9: =COUNTIFS([1]IH!$S:$S,"DISBURSED",[1]IH!$M:$M,B9) -> 3 | H9: =F9+G9 -> 8 | I9: =IFERROR((F9/C9),0) -> 0.625 | J9: =IFERROR((G9/D9),0) -> 1 | K9: =IFERROR((H9/E9),0) -> 0.72727273 | L9: SALMAN | M9: ARENA | N9: =COUNTIFS(RETAIL!K:K,"*TOUR*",RETAIL!N:N,B9) -> 5 | P9: KADAVANTHRA | Q9: 7 | R9: 3 | S9: =Q9+R9 -> 10 | T9: 4 | U9: 1 | V9: =T9+U9 -> 5 | W9: =IFERROR((T9/Q9),0) -> 0.57142857 | X9: =IFERROR((U9/R9),0) -> 0.33333333 | Y9: =IFERROR((V9/S9),0) -> 0.5
B10: KAIPAMANGALAM | C10: =COUNTIFS(RETAIL!N:N,B10) -> 19 | D10: =COUNTIFS([1]RETAIL!$N:$N,B10) -> 6 | E10: =C10+D10 -> 25 | F10: =COUNTIFS(IH!M:M,B10,IH!S:S,"DISBURSED") -> 11 | G10: =COUNTIFS([1]IH!$S:$S,"DISBURSED",[1]IH!$M:$M,B10) -> 6 | H10: =F10+G10 -> 17 | I10: =IFERROR((F10/C10),0) -> 0.57894737 | J10: =IFERROR((G10/D10),0) -> 1 | K10: =IFERROR((H10/E10),0) -> 0.68 | L10: JINEESH | M10: STUDIO | N10: =COUNTIFS(RETAIL!K:K,"*TOUR*",RETAIL!N:N,B10) -> 9 | P10: KAIPAMANGALAM | Q10: 16 | R10: 4 | S10: =Q10+R10 -> 20 | T10: 11 | U10: 3 | V10: =T10+U10 -> 14 | W10: =IFERROR((T10/Q10),0) -> 0.6875 | X10: =IFERROR((U10/R10),0) -> 0.75 | Y10: =IFERROR((V10/S10),0) -> 0.7
B11: KODUNGALLUR | C11: =COUNTIFS(RETAIL!N:N,B11) -> 13 | D11: =COUNTIFS([1]RETAIL!$N:$N,B11) -> 10 | E11: =C11+D11 -> 23 | F11: =COUNTIFS(IH!M:M,B11,IH!S:S,"DISBURSED") -> 8 | G11: =COUNTIFS([1]IH!$S:$S,"DISBURSED",[1]IH!$M:$M,B11) -> 7 | H11: =F11+G11 -> 15 | I11: =IFERROR((F11/C11),0) -> 0.61538462 | J11: =IFERROR((G11/D11),0) -> 0.7 | K11: =IFERROR((H11/E11),0) -> 0.65217391 | L11: JINEESH | M11: STUDIO | N11: =COUNTIFS(RETAIL!K:K,"*TOUR*",RETAIL!N:N,B11) -> 5 | P11: KODUNGALLOOR | Q11: 11 | R11: 5 | S11: =Q11+R11 -> 16 | T11: 11 | U11: 2 | V11: =T11+U11 -> 13 | W11: =IFERROR((T11/Q11),0) -> 1 | X11: =IFERROR((U11/R11),0) -> 0.4 | Y11: =IFERROR((V11/S11),0) -> 0.8125
B12: KOLENCHERY | C12: =COUNTIFS(RETAIL!N:N,B12) -> 9 | D12: =COUNTIFS([1]RETAIL!$N:$N,B12) -> 5 | E12: =C12+D12 -> 14 | F12: =COUNTIFS(IH!M:M,B12,IH!S:S,"DISBURSED") -> 7 | G12: =COUNTIFS([1]IH!$S:$S,"DISBURSED",[1]IH!$M:$M,B12) -> 4 | H12: =F12+G12 -> 11 | I12: =IFERROR((F12/C12),0) -> 0.77777778 | J12: =IFERROR((G12/D12),0) -> 0.8 | K12: =IFERROR((H12/E12),0) -> 0.78571429 | L12: AMAL | M12: ARENA | N12: =COUNTIFS(RETAIL!K:K,"*TOUR*",RETAIL!N:N,B12) -> 0 | P12: KOLENCHERRY | Q12: 11 | R12: 2 | S12: =Q12+R12 -> 13 | T12: 6 | U12: 1 | V12: =T12+U12 -> 7 | W12: =IFERROR((T12/Q12),0) -> 0.54545455 | X12: =IFERROR((U12/R12),0) -> 0.5 | Y12: =IFERROR((V12/S12),0) -> 0.53846154
B13: KOOTHATTUKULAM | C13: =COUNTIFS(RETAIL!N:N,B13) -> 11 | D13: =COUNTIFS([1]RETAIL!$N:$N,B13) -> 0 | E13: =C13+D13 -> 11 | F13: =COUNTIFS(IH!M:M,B13,IH!S:S,"DISBURSED") -> 6 | G13: =COUNTIFS([1]IH!$S:$S,"DISBURSED",[1]IH!$M:$M,B13) -> 0 | H13: =F13+G13 -> 6 | I13: =IFERROR((F13/C13),0) -> 0.54545455 | J13: =IFERROR((G13/D13),0) -> 0 | K13: =IFERROR((H13/E13),0) -> 0.54545455 | L13: AMAL | M13: ARENA | N13: =COUNTIFS(RETAIL!K:K,"*TOUR*",RETAIL!N:N,B13) -> 1 | P13: KOOTHATTUKULAM | Q13: 18 | R13: 13 | S13: =Q13+R13 -> 31 | T13: 8 | U13: 9 | V13: =T13+U13 -> 17 | W13: =IFERROR((T13/Q13),0) -> 0.44444444 | X13: =IFERROR((U13/R13),0) -> 0.69230769 | Y13: =IFERROR((V13/S13),0) -> 0.5483871
B14: PERUMBAVOOR | C14: =COUNTIFS(RETAIL!N:N,B14) -> 12 | D14: =COUNTIFS([1]RETAIL!$N:$N,B14) -> 4 | E14: =C14+D14 -> 16 | F14: =COUNTIFS(IH!M:M,B14,IH!S:S,"DISBURSED") -> 9 | G14: =COUNTIFS([1]IH!$S:$S,"DISBURSED",[1]IH!$M:$M,B14) -> 3 | H14: =F14+G14 -> 12 | I14: =IFERROR((F14/C14),0) -> 0.75 | J14: =IFERROR((G14/D14),0) -> 0.75 | K14: =IFERROR((H14/E14),0) -> 0.75 | L14: SALMAN | M14: ARENA | N14: =COUNTIFS(RETAIL!K:K,"*TOUR*",RETAIL!N:N,B14) -> 0 | P14: PERUMBAVOOR | Q14: 14 | R14: 1 | S14: =Q14+R14 -> 15 | T14: 10 | U14: 1 | V14: =T14+U14 -> 11 | W14: =IFERROR((T14/Q14),0) -> 0.71428571 | X14: =IFERROR((U14/R14),0) -> 1 | Y14: =IFERROR((V14/S14),0) -> 0.73333333
B15: PIRAVOM | C15: =COUNTIFS(RETAIL!N:N,B15) -> 14 | D15: =COUNTIFS([1]RETAIL!$N:$N,B15) -> 0 | E15: =C15+D15 -> 14 | F15: =COUNTIFS(IH!M:M,B15,IH!S:S,"DISBURSED") -> 6 | G15: =COUNTIFS([1]IH!$S:$S,"DISBURSED",[1]IH!$M:$M,B15) -> 0 | H15: =F15+G15 -> 6 | I15: =IFERROR((F15/C15),0) -> 0.42857143 | J15: =IFERROR((G15/D15),0) -> 0 | K15: =IFERROR((H15/E15),0) -> 0.42857143 | L15: AMAL | M15: ARENA | N15: =COUNTIFS(RETAIL!K:K,"*TOUR*",RETAIL!N:N,B15) -> 4 | P15: PIRAVOM | Q15: 10 | R15: 2 | S15: =Q15+R15 -> 12 | T15: 9 | U15: 0 | V15: =T15+U15 -> 9 | W15: =IFERROR((T15/Q15),0) -> 0.9 | X15: =IFERROR((U15/R15),0) -> 0 | Y15: =IFERROR((V15/S15),0) -> 0.75
... B20: STUDIO KPLM | C20: =COUNTIFS(RETAIL!N:N,B20) -> 0 | D20: =COUNTIFS([1]RETAIL!$N:$N,B20) -> 1 | E20: =C20+D20 -> 1 | F20: =COUNTIFS(IH!M:M,B20,IH!S:S,"DISBURSED") -> 0 | G20: =COUNTIFS([1]IH!$S:$S,"DISBURSED",[1]IH!$M:$M,B20) -> 1 | H20: =F20+G20 -> 1 | I20: =IFERROR((F20/C20),0) -> 0 | J20: =IFERROR((G20/D20),0) -> 1 | K20: =IFERROR((H20/E20),0) -> 1 | L20: JINEESH | M20: STUDIO | N20: =COUNTIFS(RETAIL!K:K,"*TOUR*",RETAIL!N:N,B20) -> 0 | P20: STUDIO KPLM | Q20: 0 | R20: 5 | S20: =Q20+R20 -> 5 | T20: 0 | U20: 3 | V20: =T20+U20 -> 3 | W20: =IFERROR((T20/Q20),0) -> 0 | X20: =IFERROR((U20/R20),0) -> 0.6 | Y20: =IFERROR((V20/S20),0) -> 0.6
B21: TOTAL | C21: =SUM(C4:C20) -> 185 | D21: =SUM(D4:D20) -> 125 | E21: =SUM(C21+D21) -> 310 | F21: =SUM(F4:F20) -> 109 | G21: =SUM(G4:G20) -> 88 | H21: =F21+G21 -> 197 | I21: =IFERROR((F21/C21),0) -> 0.58918919 | J21: =IFERROR((G21/D21),0) -> 0.704 | K21: =IFERROR((H21/E21),0) -> 0.63548387 | N21: =SUM(N4:N20) -> 77 | P21: TOTAL | Q21: =SUM(Q4:Q20) -> 200 | R21: =SUM(R4:R20) -> 123 | S21: =Q21+R21 -> 323 | T21: =SUM(T4:T20) -> 123 | U21: =SUM(U4:U20) -> 76 | V21: =T21+U21 -> 199 | W21: =IFERROR((T21/Q21),0) -> 0.615 | X21: =IFERROR((U21/R21),0) -> 0.61788618 | Y21: =IFERROR((V21/S21),0) -> 0.61609907
N22: =N21/C21 -> 0.41621622
B24: ARENA COCHIN | C24: {=SUMPRODUCT(C4:C17)} -> 174 | D24: {=SUMPRODUCT(D4:D17)} -> 49 | E24: =C24+D24 -> 223 | F24: {=SUMPRODUCT(F4:F17)} -> 104 | G24: {=SUMPRODUCT(G4:G17)} -> 38 | H24: =F24+G24 -> 142 | I24: =IFERROR((F24/C24),0) -> 0.59770115 | J24: =IFERROR((G24/D24),0) -> 0.7755102 | K24: =IFERROR((H24/E24),0) -> 0.6367713 | P24: Finance Cordinator wise Performance - Jan-26
B25: NEXA COCHIN | C25: =SUMPRODUCT(C18) -> 10 | D25: =SUMPRODUCT(D18) -> 70 | E25: =C25+D25 -> 80 | F25: =SUMPRODUCT(F18) -> 4 | G25: =SUMPRODUCT(G18) -> 45 | H25: =F25+G25 -> 49 | I25: =IFERROR((F25/C25),0) -> 0.4 | J25: =IFERROR((G25/D25),0) -> 0.64285714 | K25: =IFERROR((H25/E25),0) -> 0.6125 | Q25: ARENA | T25: NEXA | W25: TOTAL
B26: STUDIO | C26: {=SUMPRODUCT(C19:C20)} -> 1 | D26: {=SUMPRODUCT(D19:D20)} -> 6 | E26: =C26+D26 -> 7 | F26: {=SUMPRODUCT(F19:F20)} -> 1 | G26: {=SUMPRODUCT(G19:G20)} -> 5 | H26: =F26+G26 -> 6 | I26: =IFERROR((F26/C26),0) -> 1 | J26: =IFERROR((G26/D26),0) -> 0.83333333 | K26: =IFERROR((H26/E26),0) -> 0.85714286 | P26: COORDINATOR | Q26: RETAIL | R26: IH Fin | S26: PENT% | T26: RETAIL | U26: IH Fin | V26: PENT% | W26: RETAIL | X26: IH Fin | Y26: PENT%
B27: TOTAL | C27: =SUM(C24:C26) -> 185 | D27: =SUM(D24:D26) -> 125 | E27: =C27+D27 -> 310 | F27: =SUM(F24:F26) -> 109 | G27: =SUM(G24:G26) -> 88 | H27: =F27+G27 -> 197 | I27: =IFERROR((F27/C27),0) -> 0.58918919 | J27: =IFERROR((G27/D27),0) -> 0.704 | K27: =IFERROR((H27/E27),0) -> 0.63548387 | P27: SIVAPRASAD | Q27: =SUMIFS($Q$4:$Q$20,$L$4:$L$20,P27) -> 60 | R27: =SUMIFS($T$4:$T$20,$L$4:$L$20,P27) -> 37 | S27: =IFERROR((R27/Q27),0) -> 0.61666667 | T27: =SUMIFS($R$4:$R$20,$L$4:$L$20,P27) -> 10 | U27: =SUMIFS($U$4:$U$20,$L$4:$L$20,P27) -> 9 | V27: =IFERROR((U27/T27),0) -> 0.9 | W27: =Q27+T27 -> 70 | X27: =R27+U27 -> 46 | Y27: =IFERROR((X27/W27),0) -> 0.65714286
P28: AMAL | Q28: =SUMIFS($Q$4:$Q$20,$L$4:$L$20,P28) -> 39 | R28: =SUMIFS($T$4:$T$20,$L$4:$L$20,P28) -> 23 | S28: =IFERROR((R28/Q28),0) -> 0.58974359 | T28: =SUMIFS($R$4:$R$20,$L$4:$L$20,P28) -> 17 | U28: =SUMIFS($U$4:$U$20,$L$4:$L$20,P28) -> 10 | V28: =IFERROR((U28/T28),0) -> 0.58823529 | W28: =Q28+T28 -> 56 | X28: =R28+U28 -> 33 | Y28: =IFERROR((X28/W28),0) -> 0.58928571
P29: SALMAN | Q29: =SUMIFS($Q$4:$Q$20,$L$4:$L$20,P29) -> 25 | R29: =SUMIFS($T$4:$T$20,$L$4:$L$20,P29) -> 15 | S29: =IFERROR((R29/Q29),0) -> 0.6 | T29: =SUMIFS($R$4:$R$20,$L$4:$L$20,P29) -> 5 | U29: =SUMIFS($U$4:$U$20,$L$4:$L$20,P29) -> 3 | V29: =IFERROR((U29/T29),0) -> 0.6 | W29: =Q29+T29 -> 30 | X29: =R29+U29 -> 18 | Y29: =IFERROR((X29/W29),0) -> 0.6
P30: SINTO | Q30: =SUMIFS($Q$4:$Q$20,$L$4:$L$20,P30) -> 35 | R30: =SUMIFS($T$4:$T$20,$L$4:$L$20,P30) -> 18 | S30: =IFERROR((R30/Q30),0) -> 0.51428571 | T30: =SUMIFS($R$4:$R$20,$L$4:$L$20,P30) -> 6 | U30: =SUMIFS($U$4:$U$20,$L$4:$L$20,P30) -> 5 | V30: =IFERROR((U30/T30),0) -> 0.83333333 | W30: =Q30+T30 -> 41 | X30: =R30+U30 -> 23 | Y30: =IFERROR((X30/W30),0) -> 0.56097561
P31: JINEESH | Q31: =SUMIFS($Q$4:$Q$20,$L$4:$L$20,P31) -> 30 | R31: =SUMIFS($T$4:$T$20,$L$4:$L$20,P31) -> 24 | S31: =IFERROR((R31/Q31),0) -> 0.8 | T31: =SUMIFS($R$4:$R$20,$L$4:$L$20,P31) -> 19 | U31: =SUMIFS($U$4:$U$20,$L$4:$L$20,P31) -> 9 | V31: =IFERROR((U31/T31),0) -> 0.47368421 | W31: =Q31+T31 -> 49 | X31: =R31+U31 -> 33 | Y31: =IFERROR((X31/W31),0) -> 0.67346939
P32: WILSON | Q32: =SUMIFS($Q$4:$Q$20,$L$4:$L$20,P32) -> 11 | R32: =SUMIFS($T$4:$T$20,$L$4:$L$20,P32) -> 6 | S32: =IFERROR((R32/Q32),0) -> 0.54545455 | T32: =SUMIFS($R$4:$R$20,$L$4:$L$20,P32) -> 66 | U32: =SUMIFS($U$4:$U$20,$L$4:$L$20,P32) -> 40 | V32: =IFERROR((U32/T32),0) -> 0.60606061 | W32: =Q32+T32 -> 77 | X32: =R32+U32 -> 46 | Y32: =IFERROR((X32/W32),0) -> 0.5974026
P33: TOTAL | Q33: =SUM(Q27:Q32) -> 200 | R33: =SUM(R27:R32) -> 123 | S33: =IFERROR((R33/Q33),0) -> 0.615 | T33: =SUM(T27:T32) -> 123 | U33: =SUM(U27:U32) -> 76 | V33: =IFERROR((U33/T33),0) -> 0.61788618 | W33: =SUM(W27:W32) -> 323 | X33: =SUM(X27:X32) -> 199 | Y33: =IFERROR((X33/W33),0) -> 0.61609907

Sheet RETAIL
A1: SRL | B1: ORDER_NUMBER | C1: Enquiry_No | D1: Chassis | E1: Engine | F1: Inv_No | G1: Inv_dt | H1: Customer_id | I1: Customer_Name | J1: Model | K1: Variant_DESC | L1: DSE | M1: SRM | N1: LOCATION | O1: OUTLET | P1: Hypo | Q1: FINANCE | R1: SOURCE | S1: MSSF | T1: MSSF MAPPED | U1: MSSF STATUS | V1: IH STATUS | W1: DISBURSED DATE | X1: FINANCE CO | Y1: ERP EXECUTIVE NAME | Z1: ERP TEAM LEADER | AA1: MSSF REMARKS
A2: 1 | B2: SOB25000366 | C2: ENQ25002774 | D2: 165115 | E2: K111248 | F2: 72/VSL/25000153 | G2: 46086 | H2: 2567247652 | I2: JOSEPH JESMON | J2: VICTORIS | K2: MARUTI VICTORIS LXI CNG 1.5L 5MT | L2: VISHNU M S | M2: =VLOOKUP($L2,Emp!$A:$F,2,0) -> BINOY RAJ | N2: =VLOOKUP($L2,Emp!$A:$F,3,0) -> KODUNGALLUR | O2: =VLOOKUP($L2,Emp!$A:$F,4,0) -> ARENA | P2: CASH | Q2: CASH | R2: CASH | S2: NO | T2: =IF(_xlfn.XLOOKUP(F2,IH!Y:Y,IH!AA:AA,"")="MAPPED","MAPPED","") | U2: =IFERROR(VLOOKUP(H2,IH!C:T,18,0),"") | V2: =IF(W2<>"","DISBURSED","") | W2: =IFERROR(VLOOKUP(H2,IH!C:X,14,0),"") | X2: =VLOOKUP($L2,Emp!$A:$F,5,0) -> JINEESH | Y2: =VLOOKUP($H2,ERP!$H:$AP,33,0) -> #N/A | Z2: =VLOOKUP($H2,ERP!$H:$AP,34,0) -> #N/A
A3: 2 | B3: SOB25002218 | C3: ENQ25016028 | D3: E54170 | E3: C987571 | F3: 40/VSL/25001411 | G3: 46087 | H3: 2567242037 | I3: RANJITH T | J3: TOUR H3 | K3: MARUTI TOUR H3 CNG 1L 5MT | L3: SARATH P J | M3: =VLOOKUP($L3,Emp!$A:$F,2,0) -> SIVAPRAKASH K S | N3: =VLOOKUP($L3,Emp!$A:$F,3,0) -> THRISSUR | O3: =VLOOKUP($L3,Emp!$A:$F,4,0) -> ARENA | P3: KERALA GRAMEENA BANK | Q3: KGB | R3: IH | S3: YES | T3: =IF(_xlfn.XLOOKUP(F3,IH!Y:Y,IH!AA:AA,"")="MAPPED","MAPPED","") | U3: =IFERROR(VLOOKUP(H3,IH!C:T,18,0),"") | V3: DISBURSED | W3: FEB | X3: =VLOOKUP($L3,Emp!$A:$F,5,0) -> SINTO | Y3: =VLOOKUP($H3,ERP!$H:$AP,33,0) -> NA | Z3: =VLOOKUP($H3,ERP!$H:$AP,34,0) -> NA
A4: 3 | B4: SOB25002263 | C4: ENQ25016266 | D4: E53480 | E4: C986534 | F4: 40/VSL/25001412 | G4: 46087 | H4: 2567344451 | I4: ANSAMMA | J4: TOUR H3 | K4: MARUTI TOUR H3 CNG 1L 5MT | L4: VISHNUDAS P D | M4: =VLOOKUP($L4,Emp!$A:$F,2,0) -> SIVAPRAKASH K S | N4: =VLOOKUP($L4,Emp!$A:$F,3,0) -> THRISSUR | O4: =VLOOKUP($L4,Emp!$A:$F,4,0) -> ARENA | P4: SHRIRAM TRANSPORT FINANCE CO.LTD | Q4: SHRIRAM | R4: SELF | S4: NO | T4: =IF(_xlfn.XLOOKUP(F4,IH!Y:Y,IH!AA:AA,"")="MAPPED","MAPPED","") | U4: =IFERROR(VLOOKUP(H4,IH!C:T,18,0),"") | V4: =IF(W4<>"","DISBURSED","") | W4: =IFERROR(VLOOKUP(H4,IH!C:X,14,0),"") | X4: =VLOOKUP($L4,Emp!$A:$F,5,0) -> SINTO | Y4: =VLOOKUP($H4,ERP!$H:$AP,33,0) -> VISHNUDAS P D (C23106), | Z4: =VLOOKUP($H4,ERP!$H:$AP,34,0) -> RAJEEV (THCR)
A5: 4 | B5: SOB25002308 | C5: ENQ25016526 | D5: E53336 | E5: C986623 | F5: 40/VSL/25001413 | G5: 46087 | H5: 2567447231 | I5: SUDHI | J5: TOUR H3 | K5: MARUTI TOUR H3 CNG 1L 5MT | L5: NIDHIN C D | M5: =VLOOKUP($L5,Emp!$A:$F,2,0) -> SMITHIN P S | N5: =VLOOKUP($L5,Emp!$A:$F,3,0) -> KAIPAMANGALAM | O5: =VLOOKUP($L5,Emp!$A:$F,4,0) -> ARENA | P5: STATE BANK OF INDIA | Q5: SBI | R5: SELF | S5: NO | T5: =IF(_xlfn.XLOOKUP(F5,IH!Y:Y,IH!AA:AA,"")="MAPPED","MAPPED","") | U5: =IFERROR(VLOOKUP(H5,IH!C:T,18,0),"") | V5: =IF(W5<>"","DISBURSED","") | W5: =IFERROR(VLOOKUP(H5,IH!C:X,14,0),"") | X5: =VLOOKUP($L5,Emp!$A:$F,5,0) -> JINEESH | Y5: =VLOOKUP($H5,ERP!$H:$AP,33,0) -> NA | Z5: =VLOOKUP($H5,ERP!$H:$AP,34,0) -> NA
A6: 5 | B6: SOB25002209 | C6: ENQ25015984 | D6: E54492 | E6: C987700 | F6: 40/VSL/25001414 | G6: 46087 | H6: 2567222939 | I6: LIBIN ANTO | J6: TOUR H3 | K6: MARUTI TOUR H3 CNG 1L 5MT | L6: AMALDEV | M6: =VLOOKUP($L6,Emp!$A:$F,2,0) -> SIVAPRAKASH K S | N6: =VLOOKUP($L6,Emp!$A:$F,3,0) -> THRISSUR | O6: =VLOOKUP($L6,Emp!$A:$F,4,0) -> ARENA | P6: CASH | Q6: CASH | R6: CASH | S6: NO | T6: =IF(_xlfn.XLOOKUP(F6,IH!Y:Y,IH!AA:AA,"")="MAPPED","MAPPED","") | U6: =IFERROR(VLOOKUP(H6,IH!C:T,18,0),"") | V6: =IF(W6<>"","DISBURSED","") | W6: =IFERROR(VLOOKUP(H6,IH!C:X,14,0),"") | X6: =VLOOKUP($L6,Emp!$A:$F,5,0) -> SINTO | Y6: =VLOOKUP($H6,ERP!$H:$AP,33,0) -> NA | Z6: =VLOOKUP($H6,ERP!$H:$AP,34,0) -> BHAGIESH P (CHKD)
A7: 6 | B7: SOB25001937 | C7: ENQ25014823 | D7: E54416 | E7: 1427481 | F7: 40/VSL/25001415 | G7: 46087 | H7: 2566746837 | I7: SHIBIN K B | J7: TOUR H3 | K7: MARUTI TOUR H3 CNG 1L 5MT | L7: BINEESH P ANTO | M7: =VLOOKUP($L7,Emp!$A:$F,2,0) -> SIVAPRAKASH K S | N7: =VLOOKUP($L7,Emp!$A:$F,3,0) -> THRISSUR | O7: =VLOOKUP($L7,Emp!$A:$F,4,0) -> ARENA | P7: KERALA GRAMEENA BANK | Q7: KGB | R7: IH | S7: YES | T7: =IF(_xlfn.XLOOKUP(F7,IH!Y:Y,IH!AA:AA,"")="MAPPED","MAPPED","") | U7: =IFERROR(VLOOKUP(H7,IH!C:T,18,0),"") -> NO | V7: =IF(W7<>"","DISBURSED","") -> DISBURSED | W7: =IFERROR(VLOOKUP(H7,IH!C:X,14,0),"") -> 46087 | X7: =VLOOKUP($L7,Emp!$A:$F,5,0) -> SINTO | Y7: =VLOOKUP($H7,ERP!$H:$AP,33,0) -> BINEESH P ANTO (C22936), | Z7: =VLOOKUP($H7,ERP!$H:$AP,34,0) -> RAJEEV (THCR)
A8: 7 | B8: SOB25002150 | C8: ENQ25015563 | D8: E54510 | E8: C987803 | F8: 40/VSL/25001416 | G8: 46087 | H8: 2567087596 | I8: JAMSHEER P A | J8: TOUR H3 | K8: MARUTI TOUR H3 CNG 1L 5MT | L8: SANJAY | M8: =VLOOKUP($L8,Emp!$A:$F,2,0) -> SIVAPRAKASH K S | N8: =VLOOKUP($L8,Emp!$A:$F,3,0) -> THRISSUR | O8: =VLOOKUP($L8,Emp!$A:$F,4,0) -> ARENA | P8: KERALA GRAMEENA BANK | Q8: KGB | R8: IH | S8: NO | T8: =IF(_xlfn.XLOOKUP(F8,IH!Y:Y,IH!AA:AA,"")="MAPPED","MAPPED","") | U8: =IFERROR(VLOOKUP(H8,IH!C:T,18,0),"") -> NO | V8: =IF(W8<>"","DISBURSED","") -> DISBURSED | W8: =IFERROR(VLOOKUP(H8,IH!C:X,14,0),"") -> 46087 | X8: =VLOOKUP($L8,Emp!$A:$F,5,0) -> SINTO | Y8: =VLOOKUP($H8,ERP!$H:$AP,33,0) -> SANJAY.M.G(C26392), | Z8: =VLOOKUP($H8,ERP!$H:$AP,34,0) -> SIVAPRAKASH K.S.(TCR)
A9: 8 | B9: SOB25002176 | C9: ENQ25015701 | D9: E54635 | E9: C987892 | F9: 40/VSL/25001417 | G9: 46087 | H9: 2567161284 | I9: MIDHUN AZEEZ | J9: TOUR H3 | K9: MARUTI TOUR H3 CNG 1L 5MT | L9: SALAS JUDE | M9: =VLOOKUP($L9,Emp!$A:$F,2,0) -> NOUFAL T A | N9: =VLOOKUP($L9,Emp!$A:$F,3,0) -> EDAPPALLY | O9: =VLOOKUP($L9,Emp!$A:$F,4,0) -> ARENA | P9: KOTAK MAHINDRA PRIME LTD | Q9: KOTAK | R9: IH | S9: YES | T9: =IF(_xlfn.XLOOKUP(F9,IH!Y:Y,IH!AA:AA,"")="MAPPED","MAPPED","") | U9: =IFERROR(VLOOKUP(H9,IH!C:T,18,0),"") | V9: DISBURSED | W9: FEB | X9: =VLOOKUP($L9,Emp!$A:$F,5,0) -> SIVAPRASAD | Y9: =VLOOKUP($H9,ERP!$H:$AP,33,0) -> SALAS JUDE (C25782), | Z9: =VLOOKUP($H9,ERP!$H:$AP,34,0) -> NOUFAL T.A
